Workbook

Sheet 사용안내
A1: 건설공사 적정 공사기간 검토 (국토교통부 2026 가이드라인 기반)
B2: 공공 건설공사의 공사기간 산정기준(국토교통부 고시 제2024-1021호) 및 2026 가이드라인 적용 ▶ 금회 산정기준 : 동절기(12~익년 2월) 공사중지 미반영 — 동절기 반영은 「추가검토(동절기 반영)」 시트 참조
B4: ■ 산정 기본식
B5: 공사기간 | C5: ＝ ① 준비기간 + ② 비작업일수 + ③ 작업일수 + ④ 정리기간
B6: ③ 작업일수 | C6: ＝ 작업수량 ÷ (1일 작업량 × 투입작업조수) + 간접작업일수 + 보정일수
B7: ② 비작업일수 | C7: ＝ 기후비작업일수 + 법정공휴일수 − 중복일수(기후×공휴일÷달력일수) 〔주40시간 하한 월 8일〕
B8: 공종별 공사기간 | C8: ＝ 작업일수 + 비작업일수 → CP(주공정) 공종 합산
B9: 공사기간 | C9: ＝ 준비기간 + (CP 공종별 공사기간의 합) + 정리기간
B10: 적정성 검토 | C10: 산정값(A) vs 부록5 산정공식·실적평균(B) → |A−B|/B ≤ 20% 이면 적정
B12: ■ 시트 구성 및 사용 순서
B13: 시트 | C13: 내용
B14: ①공사개요 | C14: 공사명·시설유형·총공사비·착수일·준비/정리기간 등 기본조건 입력(노란셀)
B15: ②비작업일수 | C15: 월별 기후 비작업일수(②-1)·법정공휴일(부록1) → 월별 적용 비작업일수 자동 산정
B16: ②-1 기후비작업근거 | C16: 관측지점(전국 95개) 자동조회 + 시설유형별 권장 기상조건 자동선택(자동/수동). 하수도→하수관로 기준. 미세먼지 포함 → 월별 기후비작업일수 ②에 연동
B17: ③1일작업량DB | C17: 부록4 공종별 1일 작업량 데이터베이스 (④에서 자동 조회)
B18: ④작업일수산정 | C18: 수량집계 입력 → 부록4 매칭 시 1일작업량 자동조회 / 그 외 공종은 품셈 1일작업량 직접입력 → 작업일수 산출
B19: ⑤CP·공정순서 | C19: 순번(작업순서) 입력 → 전 단계 완료 후 착수, 같은 순번=병행, 중첩(자동/수동) 반영하여 일정 자동조정. 3단계 WBS·간트차트 자동 생성
B20: ⑥공사기간종합 | C20: 준비+CP+정리 = 총 공사기간(A), 개월 환산 및 월별 공정요약
B21: ⑦적정성검토 | C21: 부록5 산정공식 / 실적평균(B)과 비교하여 ±20% 적정성 자동 판정
B22: 추가검토(동절기 반영) | C22: 동절기(12~익년 2월) 공사중지를 반영한 경우의 추가 소요일정·순연 착공일·최종 준공일 및 발주청 조치사항. 금회 심의·제출 기준(①~⑦)은 동절기 미반영 기준임
B23: 부록참고 | C23: 부록1 법정공휴일(2026-2035)·부록2 작업제한 기상조건·부록5 산정공식
B24: 부록3DB | C24: 부록3 전국 95개 관측지점 × 13개 기상조건 월별 비작업일수 원자료 (편집 시 ②-1 자동 반영)
B26: ■ 셀 색상 안내
B27: 예시 | C27: 입력 셀 (사용자 입력)
B28: 예시 | C28: 자동 계산 셀
B29: 예시 | C29: 결과/요약 셀
B30: 예시 | C30: 검토 경고 셀
B32: ※ 본 파일은 검토 보조도구이며, 현장여건·공법·지반·기상조건에 따라 1일작업량·작업조·공정순서를 조정하여 적용해야 합니다.
B34: ■ 출력(인쇄) 안내 — 보고서 목차 대응
B35: 보고서 항목 | C35: 출력 시트 | D35: 용지 / 배율
B36: 1. 공사 개요 | C36: ①공사개요 (A1:H26) | D36: A4 세로 / 1페이지
B37: 4.3 기후여건에 따른 작업불가일수 | C37: ②-1 기후비작업근거 (A1:W74), ②-2 기후비작업근거 (A1:T77) | D37: A4 가로 / 폭 1p × 2p
B38: 4.4 월별 비작업일수 산정 | C38: ②비작업일수 (A1:L56) | D38: A4 가로 / 1페이지
B39: 5. 작업일수 (5.1~5.4) | C39: ④작업일수산정 (A1:R100), ④-1 (A1:R120), ④-2 (A1:R260), ④-3 (A1:S172) | D39: A4 가로 / 폭 1p × 2~5p
B40: 7. 주공정(CP) 구성 및 요약공정 | C40: ⑤CP구성 (A1:M80), CP공정표 (A1:BE74) — 일차·순연축 기준 산정근거 | D40: A4 가로 / ⑤ 1p×2p, CP 2p×2p
B41: 2. 공사기간 산정 / 9. 종합 | C41: ⑥공사기간종합 (인쇄영역 W3:AE13) | D41: A4 가로 / 1페이지
B42: 8. 공사기간 적정성 검토 | C42: ⑦적정성검토 (A1:I22) | D42: A4 가로 / 1페이지
B43: 9. 종합 [동절기 공사중지 고려사항] | C43: 추가검토(동절기 반영) (A1:J24) | D43: A4 가로 / 1페이지
B44: ※ 참고용(출력 제외) — 회색 탭 | C44: 사용안내, ③1일작업량DB, ⑤-1 동절기순연축, 부록참고, 부록3DB
B45: ※ 인쇄 시 위 출력 시트만 선택(Ctrl+클릭) 후 [선택 영역 인쇄]하십시오. 각 시트에는 인쇄영역·머리글·바닥글(시트명·페이지번호)이 지정되어 있습니다.
...

Sheet ①공사개요
A1: ① 공사 개요 및 기본조건
B2: 노란색 셀에 입력하세요. 회색/녹색 셀은 자동 계산됩니다.
B4: [ 사업 정보 ] | E4: [ 산정 결과 요약 ] ※ 동절기 미반영 기준
B5: 공사명 | C5: 횡산소규모 + 신서 증설 + 노동리·우정리 하수관로정비 (3개 사업 통합 공사기간 산정) | E5: ① 준비기간 | F5: =①공사개요!$C$14 -> 60 | G5: 일
B6: 발주청 | C6: 연천군 | E6: ② 비작업일수(CP) | F6: =⑥공사기간종합!$F$9 -> 927.4 | G6: 일
B7: 시설유형 | C7: 하수도 | E7: ③ 작업일수(CP) | F7: =⑥공사기간종합!$E$9 -> 1207.9 | G7: 일
B8: 총공사비(추정금액) | C8: =SUM(⑦적정성검토!C14:C16)*100 -> 29521 | D8: 백만원 | E8: ④ 정리기간 | F8: =①공사개요!$C$15 -> 30 | G8: 일
B9: └ 환산(억원) | C9: =C8/100 -> 295.21 | D9: 억원 | E9: ▶ 총 공사기간(A) | F9: =⑥공사기간종합!$H$9 -> 1064.2 | G9: 일 | H9: 동절기 미반영 기준
B10: 착수예정일(YYYY-MM-DD) | C10: 46357 | E10: (개월 환산) | F10: =⑥공사기간종합!$I$9 -> 34.987397 | G10: 개월 | H10: ≒ 35개월
B11: 기상지역(부록3 기준) | C11: 철원 | E11: ※ 통합 공사기간은 3개 사업 병행 시공(착공 시차 ② +92일, ③ +184일)을 반영한 최초 착공~최종 준공 구간이며, ②·③란의 사업별 산정값 합계와는 일치하지 않는다.
E12: [ 적정성 판정 ]
B13: [ 준비·정리기간 ] (비작업일수 미계상) | E13: 기준 공사기간(B) | F13: =TEXT(⑦적정성검토!$G$6,"#,##0")&" / "&TEXT(⑦적정성검토!$G$7,"#,##0")&" / "&TEXT(⑦적정성검토!$G$8,"#,##0") -> 658 / 819 / 996 | G13: 일
B14: ① 준비기간 | C14: =부록참고!C42 -> 60 | D14: 일 | E14: 편차율 | F14: =TEXT(⑦적정성검토!$H$6,"+0.0%;−0.0%")&" / "&TEXT(⑦적정성검토!$H$7,"+0.0%;−0.0%")&" / "&TEXT(⑦적정성검토!$H$8,"+0.0%;−0.0%") -> −15.4% / +11.0% / −5.6%
B15: ④ 정리기간 | C15: 30 | D15: 일 | E15: 판정 | F15: =⑦적정성검토!$I$6&" / "&⑦적정성검토!$I$7&" / "&⑦적정성검토!$I$8 -> 적정 / 적정 / 적정 | G15: 횡산 / 신서 / 노동리 순
B16: ※ 준비기간 예시: 상수도60·하수처리시설은 시설특성 고려 / 정리기간 준공전 1개월 범위
B17: ※ 요약란은 ⑥공사기간종합의 3개 사업 전체값(착공 시차 반영)을 참조합니다. 부록5 적정성검토 변수는 ⑦시트에 사업별로 입력하세요.
B18: [ 부록5 적정성검토용 변수 ]
B19: 총공사비 | D19: =C9 -> 295.21 | F19: 억원
B20: 연면적 | D20: 1.56 | F20: (100㎡)
B21: 지상층수 | D21: 1 | F21: (층)
B22: 지하층수 | D22: 1 | F22: (층)
B24: ※ 시설유형이 부록5 공식과 다르거나 처리시설 등 연장기반이 아닌 경우 실적평균을 활용 권장
B25: ※ 본 시트의 산정결과는 동절기(12월~익년 2월) 공사중지를 반영하지 않은 공사기간이다. 실제 공사 시에는 동절기 공사중지를 반영하여야 하며, 그 결과는 「추가검토(동절기 반영)」 시트에 별도 제시하였다.
B26: ※ 사업별 착공 시차(동절기 미반영 기준) : ① 기준(2026.12.01.), ② +92일(2027.03.03.), ③ +184일(2027.06.03.)

Sheet ②비작업일수
A1: ② 비작업일수 산정 (월별)
B2: 비작업일수 = 기후비작업일수(A) + 법정공휴일수(B) − 중복일수(C=A×B÷달력일수, 반올림) / 주40시간 하한 월 8일
B3: ※ 구조물공사(②-1)와 하수관로공사(②-2)의 월별 기후비작업일수를 비교하여 큰 값을 자동 적용합니다.
B5: 착수년도 | C5: =YEAR(①공사개요!$C$10) -> 2026 | D5: 착수월 | E5: =MONTH(①공사개요!$C$10) -> 12
B7: No | C7: 년 | D7: 월 | E7: 달력일수 | F7: 기후비작업(A) =MAX(②-1,②-2) | G7: 법정공휴일(B) | H7: 중복(C) | I7: 소계(A+B-C) | J7: 적용비작업일수 | K7: 작업가능일 | L7: 가동율
B8: 1 | C8: =$C$5+INT(($E$5-1+0)/12) -> 2026 | D8: =MOD($E$5-1+0,12)+1 -> 12 | E8: =DAY(EOMONTH(DATE(C8,D8,1),0)) -> 31 | F8: =MAX(IFERROR(INDEX('②-1 기후비작업근거'!$F$69:$Q$69,1,D8),0),IFERROR(INDEX('②-2 기후비작업근거'!$F$72:$Q$72,1,D8),0)) -> 14.4 | G8: =IFERROR(INDEX(부록참고!$B$5:$N$14,MATCH(C8,INDEX(부록참고!$B$5:$N$14,0,1),0),D8+1),0) -> 5 | H8: =ROUND(F8*G8/E8,0) -> 2 | I8: =F8+G8-H8 -> 17.4 | J8: =MAX(I8,8) -> 17.4 | K8: =E8-J8 -> 13.6 | L8: =K8/E8 -> 0.43870968 | N8: =C8*100+D8 -> 202612 | O8: =(E8-J8)/E8 -> 0.43870968
B9: 2 | C9: =$C$5+INT(($E$5-1+1)/12) -> 2027 | D9: =MOD($E$5-1+1,12)+1 -> 1 | E9: =DAY(EOMONTH(DATE(C9,D9,1),0)) -> 31 | F9: =MAX(IFERROR(INDEX('②-1 기후비작업근거'!$F$69:$Q$69,1,D9),0),IFERROR(INDEX('②-2 기후비작업근거'!$F$72:$Q$72,1,D9),0)) -> 16.7 | G9: =IFERROR(INDEX(부록참고!$B$5:$N$14,MATCH(C9,INDEX(부록참고!$B$5:$N$14,0,1),0),D9+1),0) -> 6 | H9: =ROUND(F9*G9/E9,0) -> 3 | I9: =F9+G9-H9 -> 19.7 | J9: =MAX(I9,8) -> 19.7 | K9: =E9-J9 -> 11.3 | L9: =K9/E9 -> 0.36451613 | N9: =C9*100+D9 -> 202701 | O9: =(E9-J9)/E9 -> 0.36451613
B10: 3 | C10: =$C$5+INT(($E$5-1+2)/12) -> 2027 | D10: =MOD($E$5-1+2,12)+1 -> 2 | E10: =DAY(EOMONTH(DATE(C10,D10,1),0)) -> 28 | F10: =MAX(IFERROR(INDEX('②-1 기후비작업근거'!$F$69:$Q$69,1,D10),0),IFERROR(INDEX('②-2 기후비작업근거'!$F$72:$Q$72,1,D10),0)) -> 9.9 | G10: =IFERROR(INDEX(부록참고!$B$5:$N$14,MATCH(C10,INDEX(부록참고!$B$5:$N$14,0,1),0),D10+1),0) -> 7 | H10: =ROUND(F10*G10/E10,0) -> 2 | I10: =F10+G10-H10 -> 14.9 | J10: =MAX(I10,8) -> 14.9 | K10: =E10-J10 -> 13.1 | L10: =K10/E10 -> 0.46785714 | N10: =C10*100+D10 -> 202702 | O10: =(E10-J10)/E10 -> 0.46785714
B11: 4 | C11: =$C$5+INT(($E$5-1+3)/12) -> 2027 | D11: =MOD($E$5-1+3,12)+1 -> 3 | E11: =DAY(EOMONTH(DATE(C11,D11,1),0)) -> 31 | F11: =MAX(IFERROR(INDEX('②-1 기후비작업근거'!$F$69:$Q$69,1,D11),0),IFERROR(INDEX('②-2 기후비작업근거'!$F$72:$Q$72,1,D11),0)) -> 7.5 | G11: =IFERROR(INDEX(부록참고!$B$5:$N$14,MATCH(C11,INDEX(부록참고!$B$5:$N$14,0,1),0),D11+1),0) -> 5 | H11: =ROUND(F11*G11/E11,0) -> 1 | I11: =F11+G11-H11 -> 11.5 | J11: =MAX(I11,8) -> 11.5 | K11: =E11-J11 -> 19.5 | L11: =K11/E11 -> 0.62903226 | N11: =C11*100+D11 -> 202703 | O11: =(E11-J11)/E11 -> 0.62903226
B12: 5 | C12: =$C$5+INT(($E$5-1+4)/12) -> 2027 | D12: =MOD($E$5-1+4,12)+1 -> 4 | E12: =DAY(EOMONTH(DATE(C12,D12,1),0)) -> 30 | F12: =MAX(IFERROR(INDEX('②-1 기후비작업근거'!$F$69:$Q$69,1,D12),0),IFERROR(INDEX('②-2 기후비작업근거'!$F$72:$Q$72,1,D12),0)) -> 7 | G12: =IFERROR(INDEX(부록참고!$B$5:$N$14,MATCH(C12,INDEX(부록참고!$B$5:$N$14,0,1),0),D12+1),0) -> 4 | H12: =ROUND(F12*G12/E12,0) -> 1 | I12: =F12+G12-H12 -> 10 | J12: =MAX(I12,8) -> 10 | K12: =E12-J12 -> 20 | L12: =K12/E12 -> 0.66666667 | N12: =C12*100+D12 -> 202704 | O12: =(E12-J12)/E12 -> 0.66666667
B13: 6 | C13: =$C$5+INT(($E$5-1+5)/12) -> 2027 | D13: =MOD($E$5-1+5,12)+1 -> 5 | E13: =DAY(EOMONTH(DATE(C13,D13,1),0)) -> 31 | F13: =MAX(IFERROR(INDEX('②-1 기후비작업근거'!$F$69:$Q$69,1,D13),0),IFERROR(INDEX('②-2 기후비작업근거'!$F$72:$Q$72,1,D13),0)) -> 6.9 | G13: =IFERROR(INDEX(부록참고!$B$5:$N$14,MATCH(C13,INDEX(부록참고!$B$5:$N$14,0,1),0),D13+1),0) -> 7 | H13: =ROUND(F13*G13/E13,0) -> 2 | I13: =F13+G13-H13 -> 11.9 | J13: =MAX(I13,8) -> 11.9 | K13: =E13-J13 -> 19.1 | L13: =K13/E13 -> 0.61612903 | N13: =C13*100+D13 -> 202705 | O13: =(E13-J13)/E13 -> 0.61612903
B14: 7 | C14: =$C$5+INT(($E$5-1+6)/12) -> 2027 | D14: =MOD($E$5-1+6,12)+1 -> 6 | E14: =DAY(EOMONTH(DATE(C14,D14,1),0)) -> 30 | F14: =MAX(IFERROR(INDEX('②-1 기후비작업근거'!$F$69:$Q$69,1,D14),0),IFERROR(INDEX('②-2 기후비작업근거'!$F$72:$Q$72,1,D14),0)) -> 6 | G14: =IFERROR(INDEX(부록참고!$B$5:$N$14,MATCH(C14,INDEX(부록참고!$B$5:$N$14,0,1),0),D14+1),0) -> 4 | H14: =ROUND(F14*G14/E14,0) -> 1 | I14: =F14+G14-H14 -> 9 | J14: =MAX(I14,8) -> 9 | K14: =E14-J14 -> 21 | L14: =K14/E14 -> 0.7 | N14: =C14*100+D14 -> 202706 | O14: =(E14-J14)/E14 -> 0.7
B15: 8 | C15: =$C$5+INT(($E$5-1+7)/12) -> 2027 | D15: =MOD($E$5-1+7,12)+1 -> 7 | E15: =DAY(EOMONTH(DATE(C15,D15,1),0)) -> 31 | F15: =MAX(IFERROR(INDEX('②-1 기후비작업근거'!$F$69:$Q$69,1,D15),0),IFERROR(INDEX('②-2 기후비작업근거'!$F$72:$Q$72,1,D15),0)) -> 16.3 | G15: =IFERROR(INDEX(부록참고!$B$5:$N$14,MATCH(C15,INDEX(부록참고!$B$5:$N$14,0,1),0),D15+1),0) -> 4 | H15: =ROUND(F15*G15/E15,0) -> 2 | I15: =F15+G15-H15 -> 18.3 | J15: =MAX(I15,8) -> 18.3 | K15: =E15-J15 -> 12.7 | L15: =K15/E15 -> 0.40967742 | N15: =C15*100+D15 -> 202707 | O15: =(E15-J15)/E15 -> 0.40967742
B16: 9 | C16: =$C$5+INT(($E$5-1+8)/12) -> 2027 | D16: =MOD($E$5-1+8,12)+1 -> 8 | E16: =DAY(EOMONTH(DATE(C16,D16,1),0)) -> 31 | F16: =MAX(IFERROR(INDEX('②-1 기후비작업근거'!$F$69:$Q$69,1,D16),0),IFERROR(INDEX('②-2 기후비작업근거'!$F$72:$Q$72,1,D16),0)) -> 17.9 | G16: =IFERROR(INDEX(부록참고!$B$5:$N$14,MATCH(C16,INDEX(부록참고!$B$5:$N$14,0,1),0),D16+1),0) -> 6 | H16: =ROUND(F16*G16/E16,0) -> 3 | I16: =F16+G16-H16 -> 20.9 | J16: =MAX(I16,8) -> 20.9 | K16: =E16-J16 -> 10.1 | L16: =K16/E16 -> 0.32580645 | N16: =C16*100+D16 -> 202708 | O16: =(E16-J16)/E16 -> 0.32580645
B17: 10 | C17: =$C$5+INT(($E$5-1+9)/12) -> 2027 | D17: =MOD($E$5-1+9,12)+1 -> 9 | E17: =DAY(EOMONTH(DATE(C17,D17,1),0)) -> 30 | F17: =MAX(IFERROR(INDEX('②-1 기후비작업근거'!$F$69:$Q$69,1,D17),0),IFERROR(INDEX('②-2 기후비작업근거'!$F$72:$Q$72,1,D17),0)) -> 4.9 | G17: =IFERROR(INDEX(부록참고!$B$5:$N$14,MATCH(C17,INDEX(부록참고!$B$5:$N$14,0,1),0),D17+1),0) -> 7 | H17: =ROUND(F17*G17/E17,0) -> 1 | I17: =F17+G17-H17 -> 10.9 | J17: =MAX(I17,8) -> 10.9 | K17: =E17-J17 -> 19.1 | L17: =K17/E17 -> 0.63666667 | N17: =C17*100+D17 -> 202709 | O17: =(E17-J17)/E17 -> 0.63666667
B18: 11 | C18: =$C$5+INT(($E$5-1+10)/12) -> 2027 | D18: =MOD($E$5-1+10,12)+1 -> 10 | E18: =DAY(EOMONTH(DATE(C18,D18,1),0)) -> 31 | F18: =MAX(IFERROR(INDEX('②-1 기후비작업근거'!$F$69:$Q$69,1,D18),0),IFERROR(INDEX('②-2 기후비작업근거'!$F$72:$Q$72,1,D18),0)) -> 4.2 | G18: =IFERROR(INDEX(부록참고!$B$5:$N$14,MATCH(C18,INDEX(부록참고!$B$5:$N$14,0,1),0),D18+1),0) -> 8 | H18: =ROUND(F18*G18/E18,0) -> 1 | I18: =F18+G18-H18 -> 11.2 | J18: =MAX(I18,8) -> 11.2 | K18: =E18-J18 -> 19.8 | L18: =K18/E18 -> 0.63870968 | N18: =C18*100+D18 -> 202710 | O18: =(E18-J18)/E18 -> 0.63870968
B19: 12 | C19: =$C$5+INT(($E$5-1+11)/12) -> 2027 | D19: =MOD($E$5-1+11,12)+1 -> 11 | E19: =DAY(EOMONTH(DATE(C19,D19,1),0)) -> 30 | F19: =MAX(IFERROR(INDEX('②-1 기후비작업근거'!$F$69:$Q$69,1,D19),0),IFERROR(INDEX('②-2 기후비작업근거'!$F$72:$Q$72,1,D19),0)) -> 6.6 | G19: =IFERROR(INDEX(부록참고!$B$5:$N$14,MATCH(C19,INDEX(부록참고!$B$5:$N$14,0,1),0),D19+1),0) -> 4 | H19: =ROUND(F19*G19/E19,0) -> 1 | I19: =F19+G19-H19 -> 9.6 | J19: =MAX(I19,8) -> 9.6 | K19: =E19-J19 -> 20.4 | L19: =K19/E19 -> 0.68 | N19: =C19*100+D19 -> 202711 | O19: =(E19-J19)/E19 -> 0.68
B20: 13 | C20: =$C$5+INT(($E$5-1+12)/12) -> 2027 | D20: =MOD($E$5-1+12,12)+1 -> 12 | E20: =DAY(EOMONTH(DATE(C20,D20,1),0)) -> 31 | F20: =MAX(IFERROR(INDEX('②-1 기후비작업근거'!$F$69:$Q$69,1,D20),0),IFERROR(INDEX('②-2 기후비작업근거'!$F$72:$Q$72,1,D20),0)) -> 14.4 | G20: =IFERROR(INDEX(부록참고!$B$5:$N$14,MATCH(C20,INDEX(부록참고!$B$5:$N$14,0,1),0),D20+1),0) -> 6 | H20: =ROUND(F20*G20/E20,0) -> 3 | I20: =F20+G20-H20 -> 17.4 | J20: =MAX(I20,8) -> 17.4 | K20: =E20-J20 -> 13.6 | L20: =K20/E20 -> 0.43870968 | N20: =C20*100+D20 -> 202712 | O20: =(E20-J20)/E20 -> 0.43870968
B21: 14 | C21: =$C$5+INT(($E$5-1+13)/12) -> 2028 | D21: =MOD($E$5-1+13,12)+1 -> 1 | E21: =DAY(EOMONTH(DATE(C21,D21,1),0)) -> 31 | F21: =MAX(IFERROR(INDEX('②-1 기후비작업근거'!$F$69:$Q$69,1,D21),0),IFERROR(INDEX('②-2 기후비작업근거'!$F$72:$Q$72,1,D21),0)) -> 16.7 | G21: =IFERROR(INDEX(부록참고!$B$5:$N$14,MATCH(C21,INDEX(부록참고!$B$5:$N$14,0,1),0),D21+1),0) -> 9 | H21: =ROUND(F21*G21/E21,0) -> 5 | I21: =F21+G21-H21 -> 20.7 | J21: =MAX(I21,8) -> 20.7 | K21: =E21-J21 -> 10.3 | L21: =K21/E21 -> 0.33225806 | N21: =C21*100+D21 -> 202801 | O21: =(E21-J21)/E21 -> 0.33225806
B22: 15 | C22: =$C$5+INT(($E$5-1+14)/12) -> 2028 | D22: =MOD($E$5-1+14,12)+1 -> 2 | E22: =DAY(EOMONTH(DATE(C22,D22,1),0)) -> 29 | F22: =MAX(IFERROR(INDEX('②-1 기후비작업근거'!$F$69:$Q$69,1,D22),0),IFERROR(INDEX('②-2 기후비작업근거'!$F$72:$Q$72,1,D22),0)) -> 9.9 | G22: =IFERROR(INDEX(부록참고!$B$5:$N$14,MATCH(C22,INDEX(부록참고!$B$5:$N$14,0,1),0),D22+1),0) -> 4 | H22: =ROUND(F22*G22/E22,0) -> 1 | I22: =F22+G22-H22 -> 12.9 | J22: =MAX(I22,8) -> 12.9 | K22: =E22-J22 -> 16.1 | L22: =K22/E22 -> 0.55517241 | N22: =C22*100+D22 -> 202802 | O22: =(E22-J22)/E22 -> 0.55517241
B23: 16 | C23: =$C$5+INT(($E$5-1+15)/12) -> 2028 | D23: =MOD($E$5-1+15,12)+1 -> 3 | E23: =DAY(EOMONTH(DATE(C23,D23,1),0)) -> 31 | F23: =MAX(IFERROR(INDEX('②-1 기후비작업근거'!$F$69:$Q$69,1,D23),0),IFERROR(INDEX('②-2 기후비작업근거'!$F$72:$Q$72,1,D23),0)) -> 7.5 | G23: =IFERROR(INDEX(부록참고!$B$5:$N$14,MATCH(C23,INDEX(부록참고!$B$5:$N$14,0,1),0),D23+1),0) -> 5 | H23: =ROUND(F23*G23/E23,0) -> 1 | I23: =F23+G23-H23 -> 11.5 | J23: =MAX(I23,8) -> 11.5 | K23: =E23-J23 -> 19.5 | L23: =K23/E23 -> 0.62903226 | N23: =C23*100+D23 -> 202803
B24: 17 | C24: =$C$5+INT(($E$5-1+16)/12) -> 2028 | D24: =MOD($E$5-1+16,12)+1 -> 4 | E24: =DAY(EOMONTH(DATE(C24,D24,1),0)) -> 30 | F24: =MAX(IFERROR(INDEX('②-1 기후비작업근거'!$F$69:$Q$69,1,D24),0),IFERROR(INDEX('②-2 기후비작업근거'!$F$72:$Q$72,1,D24),0)) -> 7 | G24: =IFERROR(INDEX(부록참고!$B$5:$N$14,MATCH(C24,INDEX(부록참고!$B$5:$N$14,0,1),0),D24+1),0) -> 5 | H24: =ROUND(F24*G24/E24,0) -> 1 | I24: =F24+G24-H24 -> 11 | J24: =MAX(I24,8) -> 11 | K24: =E24-J24 -> 19 | L24: =K24/E24 -> 0.63333333 | N24: =C24*100+D24 -> 202804
B25: 18 | C25: =$C$5+INT(($E$5-1+17)/12) -> 2028 | D25: =MOD($E$5-1+17,12)+1 -> 5 | E25: =DAY(EOMONTH(DATE(C25,D25,1),0)) -> 31 | F25: =MAX(IFERROR(INDEX('②-1 기후비작업근거'!$F$69:$Q$69,1,D25),0),IFERROR(INDEX('②-2 기후비작업근거'!$F$72:$Q$72,1,D25),0)) -> 6.9 | G25: =IFERROR(INDEX(부록참고!$B$5:$N$14,MATCH(C25,INDEX(부록참고!$B$5:$N$14,0,1),0),D25+1),0) -> 6 | H25: =ROUND(F25*G25/E25,0) -> 1 | I25: =F25+G25-H25 -> 11.9 | J25: =MAX(I25,8) -> 11.9 | K25: =E25-J25 -> 19.1 | L25: =K25/E25 -> 0.61612903 | N25: =C25*100+D25 -> 202805
B26: 19 | C26: =$C$5+INT(($E$5-1+18)/12) -> 2028 | D26: =MOD($E$5-1+18,12)+1 -> 6 | E26: =DAY(EOMONTH(DATE(C26,D26,1),0)) -> 30 | F26: =MAX(IFERROR(INDEX('②-1 기후비작업근거'!$F$69:$Q$69,1,D26),0),IFERROR(INDEX('②-2 기후비작업근거'!$F$72:$Q$72,1,D26),0)) -> 6 | G26: =IFERROR(INDEX(부록참고!$B$5:$N$14,MATCH(C26,INDEX(부록참고!$B$5:$N$14,0,1),0),D26+1),0) -> 5 | H26: =ROUND(F26*G26/E26,0) -> 1 | I26: =F26+G26-H26 -> 10 | J26: =MAX(I26,8) -> 10 | K26: =E26-J26 -> 20 | L26: =K26/E26 -> 0.66666667 | N26: =C26*100+D26 -> 202806
B27: 20 | C27: =$C$5+INT(($E$5-1+19)/12) -> 2028 | D27: =MOD($E$5-1+19,12)+1 -> 7 | E27: =DAY(EOMONTH(DATE(C27,D27,1),0)) -> 31 | F27: =MAX(IFERROR(INDEX('②-1 기후비작업근거'!$F$69:$Q$69,1,D27),0),IFERROR(INDEX('②-2 기후비작업근거'!$F$72:$Q$72,1,D27),0)) -> 16.3 | G27: =IFERROR(INDEX(부록참고!$B$5:$N$14,MATCH(C27,INDEX(부록참고!$B$5:$N$14,0,1),0),D27+1),0) -> 5 | H27: =ROUND(F27*G27/E27,0) -> 3 | I27: =F27+G27-H27 -> 18.3 | J27: =MAX(I27,8) -> 18.3 | K27: =E27-J27 -> 12.7 | L27: =K27/E27 -> 0.40967742 | N27: =C27*100+D27 -> 202807
B28: 21 | C28: =$C$5+INT(($E$5-1+20)/12) -> 2028 | D28: =MOD($E$5-1+20,12)+1 -> 8 | E28: =DAY(EOMONTH(DATE(C28,D28,1),0)) -> 31 | F28: =MAX(IFERROR(INDEX('②-1 기후비작업근거'!$F$69:$Q$69,1,D28),0),IFERROR(INDEX('②-2 기후비작업근거'!$F$72:$Q$72,1,D28),0)) -> 17.9 | G28: =IFERROR(INDEX(부록참고!$B$5:$N$14,MATCH(C28,INDEX(부록참고!$B$5:$N$14,0,1),0),D28+1),0) -> 5 | H28: =ROUND(F28*G28/E28,0) -> 3 | I28: =F28+G28-H28 -> 19.9 | J28: =MAX(I28,8) -> 19.9 | K28: =E28-J28 -> 11.1 | L28: =K28/E28 -> 0.35806452 | N28: =C28*100+D28 -> 202808
B29: 22 | C29: =$C$5+INT(($E$5-1+21)/12) -> 2028 | D29: =MOD($E$5-1+21,12)+1 -> 9 | E29: =DAY(EOMONTH(DATE(C29,D29,1),0)) -> 30 | F29: =MAX(IFERROR(INDEX('②-1 기후비작업근거'!$F$69:$Q$69,1,D29),0),IFERROR(INDEX('②-2 기후비작업근거'!$F$72:$Q$72,1,D29),0)) -> 4.9 | G29: =IFERROR(INDEX(부록참고!$B$5:$N$14,MATCH(C29,INDEX(부록참고!$B$5:$N$14,0,1),0),D29+1),0) -> 4 | H29: =ROUND(F29*G29/E29,0) -> 1 | I29: =F29+G29-H29 -> 7.9 | J29: =MAX(I29,8) -> 8 | K29: =E29-J29 -> 22 | L29: =K29/E29 -> 0.73333333 | N29: =C29*100+D29 -> 202809
B30: 23 | C30: =$C$5+INT(($E$5-1+22)/12) -> 2028 | D30: =MOD($E$5-1+22,12)+1 -> 10 | E30: =DAY(EOMONTH(DATE(C30,D30,1),0)) -> 31 | F30: =MAX(IFERROR(INDEX('②-1 기후비작업근거'!$F$69:$Q$69,1,D30),0),IFERROR(INDEX('②-2 기후비작업근거'!$F$72:$Q$72,1,D30),0)) -> 4.2 | G30: =IFERROR(INDEX(부록참고!$B$5:$N$14,MATCH(C30,INDEX(부록참고!$B$5:$N$14,0,1),0),D30+1),0) -> 10 | H30: =ROUND(F30*G30/E30,0) -> 1 | I30: =F30+G30-H30 -> 13.2 | J30: =MAX(I30,8) -> 13.2 | K30: =E30-J30 -> 17.8 | L30: =K30/E30 -> 0.57419355 | N30: =C30*100+D30 -> 202810
B31: 24 | C31: =$C$5+INT(($E$5-1+23)/12) -> 2028 | D31: =MOD($E$5-1+23,12)+1 -> 11 | E31: =DAY(EOMONTH(DATE(C31,D31,1),0)) -> 30 | F31: =MAX(IFERROR(INDEX('②-1 기후비작업근거'!$F$69:$Q$69,1,D31),0),IFERROR(INDEX('②-2 기후비작업근거'!$F$72:$Q$72,1,D31),0)) -> 6.6 | G31: =IFERROR(INDEX(부록참고!$B$5:$N$14,MATCH(C31,INDEX(부록참고!$B$5:$N$14,0,1),0),D31+1),0) -> 4 | H31: =ROUND(F31*G31/E31,0) -> 1 | I31: =F31+G31-H31 -> 9.6 | J31: =MAX(I31,8) -> 9.6 | K31: =E31-J31 -> 20.4 | L31: =K31/E31 -> 0.68 | N31: =C31*100+D31 -> 202811
B32: 25 | C32: =$C$5+INT(($E$5-1+24)/12) -> 2028 | D32: =MOD($E$5-1+24,12)+1 -> 12 | E32: =DAY(EOMONTH(DATE(C32,D32,1),0)) -> 31 | F32: =MAX(IFERROR(INDEX('②-1 기후비작업근거'!$F$69:$Q$69,1,D32),0),IFERROR(INDEX('②-2 기후비작업근거'!$F$72:$Q$72,1,D32),0)) -> 14.4 | G32: =IFERROR(INDEX(부록참고!$B$5:$N$14,MATCH(C32,INDEX(부록참고!$B$5:$N$14,0,1),0),D32+1),0) -> 6 | H32: =ROUND(F32*G32/E32,0) -> 3 | I32: =F32+G32-H32 -> 17.4 | J32: =MAX(I32,8) -> 17.4 | K32: =E32-J32 -> 13.6 | L32: =K32/E32 -> 0.43870968 | N32: =C32*100+D32 -> 202812 | O32: =(E32-J32)/E32 -> 0.43870968
B33: 26 | C33: =$C$5+INT(($E$5-1+25)/12) -> 2029 | D33: =MOD($E$5-1+25,12)+1 -> 1 | E33: =DAY(EOMONTH(DATE(C33,D33,1),0)) -> 31 | F33: =MAX(IFERROR(INDEX('②-1 기후비작업근거'!$F$69:$Q$69,1,D33),0),IFERROR(INDEX('②-2 기후비작업근거'!$F$72:$Q$72,1,D33),0)) -> 16.7 | G33: =IFERROR(INDEX(부록참고!$B$5:$N$14,MATCH(C33,INDEX(부록참고!$B$5:$N$14,0,1),0),D33+1),0) -> 5 | H33: =ROUND(F33*G33/E33,0) -> 3 | I33: =F33+G33-H33 -> 18.7 | J33: =MAX(I33,8) -> 18.7 | K33: =E33-J33 -> 12.3 | L33: =K33/E33 -> 0.39677419 | N33: =C33*100+D33 -> 202901 | O33: =(E33-J33)/E33 -> 0.39677419
B34: 27 | C34: =$C$5+INT(($E$5-1+26)/12) -> 2029 | D34: =MOD($E$5-1+26,12)+1 -> 2 | E34: =DAY(EOMONTH(DATE(C34,D34,1),0)) -> 28 | F34: =MAX(IFERROR(INDEX('②-1 기후비작업근거'!$F$69:$Q$69,1,D34),0),IFERROR(INDEX('②-2 기후비작업근거'!$F$72:$Q$72,1,D34),0)) -> 9.9 | G34: =IFERROR(INDEX(부록참고!$B$5:$N$14,MATCH(C34,INDEX(부록참고!$B$5:$N$14,0,1),0),D34+1),0) -> 7 | H34: =ROUND(F34*G34/E34,0) -> 2 | I34: =F34+G34-H34 -> 14.9 | J34: =MAX(I34,8) -> 14.9 | K34: =E34-J34 -> 13.1 | L34: =K34/E34 -> 0.46785714 | N34: =C34*100+D34 -> 202902 | O34: =(E34-J34)/E34 -> 0.46785714
B35: 28 | C35: =$C$5+INT(($E$5-1+27)/12) -> 2029 | D35: =MOD($E$5-1+27,12)+1 -> 3 | E35: =DAY(EOMONTH(DATE(C35,D35,1),0)) -> 31 | F35: =MAX(IFERROR(INDEX('②-1 기후비작업근거'!$F$69:$Q$69,1,D35),0),IFERROR(INDEX('②-2 기후비작업근거'!$F$72:$Q$72,1,D35),0)) -> 7.5 | G35: =IFERROR(INDEX(부록참고!$B$5:$N$14,MATCH(C35,INDEX(부록참고!$B$5:$N$14,0,1),0),D35+1),0) -> 5 | H35: =ROUND(F35*G35/E35,0) -> 1 | I35: =F35+G35-H35 -> 11.5 | J35: =MAX(I35,8) -> 11.5 | K35: =E35-J35 -> 19.5 | L35: =K35/E35 -> 0.62903226 | N35: =C35*100+D35 -> 202903
B36: 29 | C36: =$C$5+INT(($E$5-1+28)/12) -> 2029 | D36: =MOD($E$5-1+28,12)+1 -> 4 | E36: =DAY(EOMONTH(DATE(C36,D36,1),0)) -> 30 | F36: =MAX(IFERROR(INDEX('②-1 기후비작업근거'!$F$69:$Q$69,1,D36),0),IFERROR(INDEX('②-2 기후비작업근거'!$F$72:$Q$72,1,D36),0)) -> 7 | G36: =IFERROR(INDEX(부록참고!$B$5:$N$14,MATCH(C36,INDEX(부록참고!$B$5:$N$14,0,1),0),D36+1),0) -> 5 | H36: =ROUND(F36*G36/E36,0) -> 1 | I36: =F36+G36-H36 -> 11 | J36: =MAX(I36,8) -> 11 | K36: =E36-J36 -> 19 | L36: =K36/E36 -> 0.63333333 | N36: =C36*100+D36 -> 202904
B37: 30 | C37: =$C$5+INT(($E$5-1+29)/12) -> 2029 | D37: =MOD($E$5-1+29,12)+1 -> 5 | E37: =DAY(EOMONTH(DATE(C37,D37,1),0)) -> 31 | F37: =MAX(IFERROR(INDEX('②-1 기후비작업근거'!$F$69:$Q$69,1,D37),0),IFERROR(INDEX('②-2 기후비작업근거'!$F$72:$Q$72,1,D37),0)) -> 6.9 | G37: =IFERROR(INDEX(부록참고!$B$5:$N$14,MATCH(C37,INDEX(부록참고!$B$5:$N$14,0,1),0),D37+1),0) -> 7 | H37: =ROUND(F37*G37/E37,0) -> 2 | I37: =F37+G37-H37 -> 11.9 | J37: =MAX(I37,8) -> 11.9 | K37: =E37-J37 -> 19.1 | L37: =K37/E37 -> 0.61612903 | N37: =C37*100+D37 -> 202905
B38: 31 | C38: =$C$5+INT(($E$5-1+30)/12) -> 2029 | D38: =MOD($E$5-1+30,12)+1 -> 6 | E38: =DAY(EOMONTH(DATE(C38,D38,1),0)) -> 30 | F38: =MAX(IFERROR(INDEX('②-1 기후비작업근거'!$F$69:$Q$69,1,D38),0),IFERROR(INDEX('②-2 기후비작업근거'!$F$72:$Q$72,1,D38),0)) -> 6 | G38: =IFERROR(INDEX(부록참고!$B$5:$N$14,MATCH(C38,INDEX(부록참고!$B$5:$N$14,0,1),0),D38+1),0) -> 5 | H38: =ROUND(F38*G38/E38,0) -> 1 | I38: =F38+G38-H38 -> 10 | J38: =MAX(I38,8) -> 10 | K38: =E38-J38 -> 20 | L38: =K38/E38 -> 0.66666667 | N38: =C38*100+D38 -> 202906
B39: 32 | C39: =$C$5+INT(($E$5-1+31)/12) -> 2029 | D39: =MOD($E$5-1+31,12)+1 -> 7 | E39: =DAY(EOMONTH(DATE(C39,D39,1),0)) -> 31 | F39: =MAX(IFERROR(INDEX('②-1 기후비작업근거'!$F$69:$Q$69,1,D39),0),IFERROR(INDEX('②-2 기후비작업근거'!$F$72:$Q$72,1,D39),0)) -> 16.3 | G39: =IFERROR(INDEX(부록참고!$B$5:$N$14,MATCH(C39,INDEX(부록참고!$B$5:$N$14,0,1),0),D39+1),0) -> 5 | H39: =ROUND(F39*G39/E39,0) -> 3 | I39: =F39+G39-H39 -> 18.3 | J39: =MAX(I39,8) -> 18.3 | K39: =E39-J39 -> 12.7 | L39: =K39/E39 -> 0.40967742 | N39: =C39*100+D39 -> 202907
B40: 33 | C40: =$C$5+INT(($E$5-1+32)/12) -> 2029 | D40: =MOD($E$5-1+32,12)+1 -> 8 | E40: =DAY(EOMONTH(DATE(C40,D40,1),0)) -> 31 | F40: =MAX(IFERROR(INDEX('②-1 기후비작업근거'!$F$69:$Q$69,1,D40),0),IFERROR(INDEX('②-2 기후비작업근거'!$F$72:$Q$72,1,D40),0)) -> 17.9 | G40: =IFERROR(INDEX(부록참고!$B$5:$N$14,MATCH(C40,INDEX(부록참고!$B$5:$N$14,0,1),0),D40+1),0) -> 5 | H40: =ROUND(F40*G40/E40,0) -> 3 | I40: =F40+G40-H40 -> 19.9 | J40: =MAX(I40,8) -> 19.9 | K40: =E40-J40 -> 11.1 | L40: =K40/E40 -> 0.35806452 | N40: =C40*100+D40 -> 202908
B41: 34 | C41: =$C$5+INT(($E$5-1+33)/12) -> 2029 | D41: =MOD($E$5-1+33,12)+1 -> 9 | E41: =DAY(EOMONTH(DATE(C41,D41,1),0)) -> 30 | F41: =MAX(IFERROR(INDEX('②-1 기후비작업근거'!$F$69:$Q$69,1,D41),0),IFERROR(INDEX('②-2 기후비작업근거'!$F$72:$Q$72,1,D41),0)) -> 4.9 | G41: =IFERROR(INDEX(부록참고!$B$5:$N$14,MATCH(C41,INDEX(부록참고!$B$5:$N$14,0,1),0),D41+1),0) -> 8 | H41: =ROUND(F41*G41/E41,0) -> 1 | I41: =F41+G41-H41 -> 11.9 | J41: =MAX(I41,8) -> 11.9 | K41: =E41-J41 -> 18.1 | L41: =K41/E41 -> 0.60333333 | N41: =C41*100+D41 -> 202909
B42: 35 | C42: =$C$5+INT(($E$5-1+34)/12) -> 2029 | D42: =MOD($E$5-1+34,12)+1 -> 10 | E42: =DAY(EOMONTH(DATE(C42,D42,1),0)) -> 31 | F42: =MAX(IFERROR(INDEX('②-1 기후비작업근거'!$F$69:$Q$69,1,D42),0),IFERROR(INDEX('②-2 기후비작업근거'!$F$72:$Q$72,1,D42),0)) -> 4.2 | G42: =IFERROR(INDEX(부록참고!$B$5:$N$14,MATCH(C42,INDEX(부록참고!$B$5:$N$14,0,1),0),D42+1),0) -> 6 | H42: =ROUND(F42*G42/E42,0) -> 1 | I42: =F42+G42-H42 -> 9.2 | J42: =MAX(I42,8) -> 9.2 | K42: =E42-J42 -> 21.8 | L42: =K42/E42 -> 0.70322581 | N42: =C42*100+D42 -> 202910
...

Sheet ②-1 기후비작업근거
A1: ②-1 기후 비작업일수 산정근거 (부록2 작업제한 기상조건 → 부록3 지역별 통계)
B2: 부록2의 국가건설기준(KCS 등) 작업제한 기상조건을, 부록3 기상청 10년(2015–2024) 지역통계로 일수화하여 월별 기후비작업일수를 산정합니다.
B3: 관측지점을 선택하면 13개 기상조건 값이 부록3에서 자동 반영됩니다. '선택(Y)'한 조건만 합산되며, 미세먼지는 별도 입력값을 사용합니다.
B5: ■ 관측지점 및 공사유형 선택
B6: 관측지점 | C6: =①공사개요!$C$11 -> 철원 | D6: 행정구역 | E6: =①공사개요!$C$6 -> 연천군
B7: 선택방식 | C7: 자동 | D7: 공사유형 | E7: 구조물공사
B8: ※ '자동'이면 ①공사개요의 시설유형에 따라 권장 기상조건이 자동 선택(아래 매트릭스 기준). '수동'이면 '수동선택(Y)' 칸으로 직접 지정. 하수도=하수관로 공사 기준 적용.
B10: ■ 부록2 주요 작업제한 기상조건 (해당 공종 선정 참고)
B11: 공종/작업 | C11: 작업제한 기상조건 | E11: 근거
B12: 콘크리트 타설 | C12: 강우·강설 시 원칙 금지 / 동절기 일평균 4℃↓·타설후 24h 일최저 0℃↓ → 한중콘크리트 / 혹서기 일평균 25℃↑·타설후 24h 일최고 30℃↑ → 서중콘크리트 | E12: KCS 14 20 10·40·41
B13: 일반 토공/가시설(관로 굴착) | C13: 강우·강설 시, 동절기 저온 시 작업제한 (하수·상수관로 굴착·관부설 포함) | E13: KCS 11 계열
B14: 양중/타워크레인 | C14: 순간풍속 15m/s↑ 운전중지, 10m/s↑ 설치·해체 중지 | E14: KCS 21 20 10
B15: 강구조 현장용접 | C15: 대기온도 -20℃↓, 강우·강우직후, 풍속 2m/s↑(FCAW) | E15: KCS 14 31 30
B16: 도장/방수/포장 | C16: 5℃ 미만, 강우·강설·강풍 시, 43℃↑ | E16: KCS 14 31 40
B17: 미세먼지(고농도) | C17: PM2.5 '나쁨'(일평균 36㎍/㎥↑)·비상저감조치(50㎍/㎥↑) 시 옥외작업 조정 | E17: 대기관리권역법·지자체 조례
W22: =1250/60 -> 20.833333
W23: =2*2*3.14/4*2 -> 6.28
W24: =W22/W23 -> 3.3174098
B26: ■ 시설유형별 권장 기상조건 (선택방식='자동' 시 적용) — Y=권장, 셀 수정가능
B27: 시설유형 \ 기상조건 | F27: ①체감33 | G27: ②체감35 | H27: ③최고33 | I27: ④최고35 | J27: ⑤최고0 | K27: ⑥적설5 | L27: ⑦결합 | M27: ⑧최저-12 | N27: ⑨강우3 | O27: ⑩강우5 | P27: ⑪강우10 | Q27: ⑫강우20 | R27: ⑬강풍15 | S27: ⑭미세먼지
B28: 도로포장 | L28: Y | O28: Y | S28: Y
B29: 도로(토공+교량) | F29: Y | L29: Y | P29: Y | R29: Y | S29: Y
B30: 농업용수 | F30: Y | L30: Y | P30: Y | S30: Y
B31: 상수도 | F31: Y | L31: Y | P31: Y | S31: Y
B32: 하수도 | F32: Y | L32: Y | P32: Y | S32: Y
B33: 철도(궤도) | F33: Y | L33: Y | P33: Y | R33: Y | S33: Y
B34: 학교 | F34: Y | L34: Y | O34: Y | R34: Y | S34: Y
B35: 청사 | F35: Y | L35: Y | O35: Y | R35: Y | S35: Y
B36: 기타건축물 | F36: Y | L36: Y | O36: Y | R36: Y | S36: Y
B37: 기타 | F37: Y | L37: Y | O37: Y | R37: Y | S37: Y
B38: ※ 하수도=하수관로(토공·관부설) 기준 → 혹서기 폭염(체감33)·동절기 결합·강우10㎜·미세먼지 권장. 구조물(학교·청사 등)은 강우5㎜·강풍 포함. 셀의 Y/공백을 수정하면 권장이 바뀝니다.
B53: ■ 기상조건별 비작업일수 (선택지점 자동조회, 2015–2024 월평균) — 선택=위 방식(자동:권장/수동:수동선택)
B54: 선택 | C54: 구분 | D54: 기상조건 | E54: 근거/기준 | F54: 1월 | G54: 2월 | H54: 3월 | I54: 4월 | J54: 5월 | K54: 6월 | L54: 7월 | M54: 8월 | N54: 9월 | O54: 10월 | P54: 11월 | Q54: 12월 | R54: 소계 | S54: 수동선택 | T54: 권장
B55: =IF('②-1 기후비작업근거'!$C$7="자동",$T55,$S55) -> Y | C55: 혹서기 | D55: 체감온도 33℃ 이상 | E55: 서중콘크리트/폭염 KCS 14 20 41 | F55: =IFERROR(INDEX(부록3DB!$J$7:$U$1241,MATCH('②-1 기후비작업근거'!$C$6&"|"&1,부록3DB!$I$7:$I$1241,0),1),0) -> 0 | G55: =IFERROR(INDEX(부록3DB!$J$7:$U$1241,MATCH('②-1 기후비작업근거'!$C$6&"|"&1,부록3DB!$I$7:$I$1241,0),2),0) -> 0 | H55: =IFERROR(INDEX(부록3DB!$J$7:$U$1241,MATCH('②-1 기후비작업근거'!$C$6&"|"&1,부록3DB!$I$7:$I$1241,0),3),0) -> 0 | I55: =IFERROR(INDEX(부록3DB!$J$7:$U$1241,MATCH('②-1 기후비작업근거'!$C$6&"|"&1,부록3DB!$I$7:$I$1241,0),4),0) -> 0 | J55: =IFERROR(INDEX(부록3DB!$J$7:$U$1241,MATCH('②-1 기후비작업근거'!$C$6&"|"&1,부록3DB!$I$7:$I$1241,0),5),0) -> 0 | K55: =IFERROR(INDEX(부록3DB!$J$7:$U$1241,MATCH('②-1 기후비작업근거'!$C$6&"|"&1,부록3DB!$I$7:$I$1241,0),6),0) -> 0 | L55: =IFERROR(INDEX(부록3DB!$J$7:$U$1241,MATCH('②-1 기후비작업근거'!$C$6&"|"&1,부록3DB!$I$7:$I$1241,0),7),0) -> 5.7 | M55: =IFERROR(INDEX(부록3DB!$J$7:$U$1241,MATCH('②-1 기후비작업근거'!$C$6&"|"&1,부록3DB!$I$7:$I$1241,0),8),0) -> 9.2 | N55: =IFERROR(INDEX(부록3DB!$J$7:$U$1241,MATCH('②-1 기후비작업근거'!$C$6&"|"&1,부록3DB!$I$7:$I$1241,0),9),0) -> 0.1 | O55: =IFERROR(INDEX(부록3DB!$J$7:$U$1241,MATCH('②-1 기후비작업근거'!$C$6&"|"&1,부록3DB!$I$7:$I$1241,0),10),0) -> 0 | P55: =IFERROR(INDEX(부록3DB!$J$7:$U$1241,MATCH('②-1 기후비작업근거'!$C$6&"|"&1,부록3DB!$I$7:$I$1241,0),11),0) -> 0 | Q55: =IFERROR(INDEX(부록3DB!$J$7:$U$1241,MATCH('②-1 기후비작업근거'!$C$6&"|"&1,부록3DB!$I$7:$I$1241,0),12),0) -> 0 | R55: =SUM(F55:Q55) -> 15 | S55: Y | T55: =IFERROR(IF(INDEX('②-1 기후비작업근거'!$F$28:$S$37,MATCH(①공사개요!$C$7,'②-1 기후비작업근거'!$B$28:$B$37,0),1)="Y","Y",""),"") -> Y
B56: =IF('②-1 기후비작업근거'!$C$7="자동",$T56,$S56) | C56: 혹서기 | D56: 체감온도 35℃ 이상 | E56: 폭염경보 기준 | F56: =IFERROR(INDEX(부록3DB!$J$7:$U$1241,MATCH('②-1 기후비작업근거'!$C$6&"|"&2,부록3DB!$I$7:$I$1241,0),1),0) -> 0 | G56: =IFERROR(INDEX(부록3DB!$J$7:$U$1241,MATCH('②-1 기후비작업근거'!$C$6&"|"&2,부록3DB!$I$7:$I$1241,0),2),0) -> 0 | H56: =IFERROR(INDEX(부록3DB!$J$7:$U$1241,MATCH('②-1 기후비작업근거'!$C$6&"|"&2,부록3DB!$I$7:$I$1241,0),3),0) -> 0 | I56: =IFERROR(INDEX(부록3DB!$J$7:$U$1241,MATCH('②-1 기후비작업근거'!$C$6&"|"&2,부록3DB!$I$7:$I$1241,0),4),0) -> 0 | J56: =IFERROR(INDEX(부록3DB!$J$7:$U$1241,MATCH('②-1 기후비작업근거'!$C$6&"|"&2,부록3DB!$I$7:$I$1241,0),5),0) -> 0 | K56: =IFERROR(INDEX(부록3DB!$J$7:$U$1241,MATCH('②-1 기후비작업근거'!$C$6&"|"&2,부록3DB!$I$7:$I$1241,0),6),0) -> 0 | L56: =IFERROR(INDEX(부록3DB!$J$7:$U$1241,MATCH('②-1 기후비작업근거'!$C$6&"|"&2,부록3DB!$I$7:$I$1241,0),7),0) -> 0.9 | M56: =IFERROR(INDEX(부록3DB!$J$7:$U$1241,MATCH('②-1 기후비작업근거'!$C$6&"|"&2,부록3DB!$I$7:$I$1241,0),8),0) -> 1.8 | N56: =IFERROR(INDEX(부록3DB!$J$7:$U$1241,MATCH('②-1 기후비작업근거'!$C$6&"|"&2,부록3DB!$I$7:$I$1241,0),9),0) -> 0 | O56: =IFERROR(INDEX(부록3DB!$J$7:$U$1241,MATCH('②-1 기후비작업근거'!$C$6&"|"&2,부록3DB!$I$7:$I$1241,0),10),0) -> 0 | P56: =IFERROR(INDEX(부록3DB!$J$7:$U$1241,MATCH('②-1 기후비작업근거'!$C$6&"|"&2,부록3DB!$I$7:$I$1241,0),11),0) -> 0 | Q56: =IFERROR(INDEX(부록3DB!$J$7:$U$1241,MATCH('②-1 기후비작업근거'!$C$6&"|"&2,부록3DB!$I$7:$I$1241,0),12),0) -> 0 | R56: =SUM(F56:Q56) -> 2.7 | T56: =IFERROR(IF(INDEX('②-1 기후비작업근거'!$F$28:$S$37,MATCH(①공사개요!$C$7,'②-1 기후비작업근거'!$B$28:$B$37,0),2)="Y","Y",""),"")
B57: =IF('②-1 기후비작업근거'!$C$7="자동",$T57,$S57) | C57: 혹서기 | D57: 일최고온도 33℃ 이상 | E57: 서중콘크리트 참고 | F57: =IFERROR(INDEX(부록3DB!$J$7:$U$1241,MATCH('②-1 기후비작업근거'!$C$6&"|"&3,부록3DB!$I$7:$I$1241,0),1),0) -> 0 | G57: =IFERROR(INDEX(부록3DB!$J$7:$U$1241,MATCH('②-1 기후비작업근거'!$C$6&"|"&3,부록3DB!$I$7:$I$1241,0),2),0) -> 0 | H57: =IFERROR(INDEX(부록3DB!$J$7:$U$1241,MATCH('②-1 기후비작업근거'!$C$6&"|"&3,부록3DB!$I$7:$I$1241,0),3),0) -> 0 | I57: =IFERROR(INDEX(부록3DB!$J$7:$U$1241,MATCH('②-1 기후비작업근거'!$C$6&"|"&3,부록3DB!$I$7:$I$1241,0),4),0) -> 0 | J57: =IFERROR(INDEX(부록3DB!$J$7:$U$1241,MATCH('②-1 기후비작업근거'!$C$6&"|"&3,부록3DB!$I$7:$I$1241,0),5),0) -> 0 | K57: =IFERROR(INDEX(부록3DB!$J$7:$U$1241,MATCH('②-1 기후비작업근거'!$C$6&"|"&3,부록3DB!$I$7:$I$1241,0),6),0) -> 0.7 | L57: =IFERROR(INDEX(부록3DB!$J$7:$U$1241,MATCH('②-1 기후비작업근거'!$C$6&"|"&3,부록3DB!$I$7:$I$1241,0),7),0) -> 3.7 | M57: =IFERROR(INDEX(부록3DB!$J$7:$U$1241,MATCH('②-1 기후비작업근거'!$C$6&"|"&3,부록3DB!$I$7:$I$1241,0),8),0) -> 6 | N57: =IFERROR(INDEX(부록3DB!$J$7:$U$1241,MATCH('②-1 기후비작업근거'!$C$6&"|"&3,부록3DB!$I$7:$I$1241,0),9),0) -> 0.1 | O57: =IFERROR(INDEX(부록3DB!$J$7:$U$1241,MATCH('②-1 기후비작업근거'!$C$6&"|"&3,부록3DB!$I$7:$I$1241,0),10),0) -> 0 | P57: =IFERROR(INDEX(부록3DB!$J$7:$U$1241,MATCH('②-1 기후비작업근거'!$C$6&"|"&3,부록3DB!$I$7:$I$1241,0),11),0) -> 0 | Q57: =IFERROR(INDEX(부록3DB!$J$7:$U$1241,MATCH('②-1 기후비작업근거'!$C$6&"|"&3,부록3DB!$I$7:$I$1241,0),12),0) -> 0 | R57: =SUM(F57:Q57) -> 10.5 | T57: =IFERROR(IF(INDEX('②-1 기후비작업근거'!$F$28:$S$37,MATCH(①공사개요!$C$7,'②-1 기후비작업근거'!$B$28:$B$37,0),3)="Y","Y",""),"")
B58: =IF('②-1 기후비작업근거'!$C$7="자동",$T58,$S58) | C58: 혹서기 | D58: 일최고온도 35℃ 이상 | E58: 폭염특보 | F58: =IFERROR(INDEX(부록3DB!$J$7:$U$1241,MATCH('②-1 기후비작업근거'!$C$6&"|"&4,부록3DB!$I$7:$I$1241,0),1),0) -> 0 | G58: =IFERROR(INDEX(부록3DB!$J$7:$U$1241,MATCH('②-1 기후비작업근거'!$C$6&"|"&4,부록3DB!$I$7:$I$1241,0),2),0) -> 0 | H58: =IFERROR(INDEX(부록3DB!$J$7:$U$1241,MATCH('②-1 기후비작업근거'!$C$6&"|"&4,부록3DB!$I$7:$I$1241,0),3),0) -> 0 | I58: =IFERROR(INDEX(부록3DB!$J$7:$U$1241,MATCH('②-1 기후비작업근거'!$C$6&"|"&4,부록3DB!$I$7:$I$1241,0),4),0) -> 0 | J58: =IFERROR(INDEX(부록3DB!$J$7:$U$1241,MATCH('②-1 기후비작업근거'!$C$6&"|"&4,부록3DB!$I$7:$I$1241,0),5),0) -> 0 | K58: =IFERROR(INDEX(부록3DB!$J$7:$U$1241,MATCH('②-1 기후비작업근거'!$C$6&"|"&4,부록3DB!$I$7:$I$1241,0),6),0) -> 0.1 | L58: =IFERROR(INDEX(부록3DB!$J$7:$U$1241,MATCH('②-1 기후비작업근거'!$C$6&"|"&4,부록3DB!$I$7:$I$1241,0),7),0) -> 0.9 | M58: =IFERROR(INDEX(부록3DB!$J$7:$U$1241,MATCH('②-1 기후비작업근거'!$C$6&"|"&4,부록3DB!$I$7:$I$1241,0),8),0) -> 0.8 | N58: =IFERROR(INDEX(부록3DB!$J$7:$U$1241,MATCH('②-1 기후비작업근거'!$C$6&"|"&4,부록3DB!$I$7:$I$1241,0),9),0) -> 0 | O58: =IFERROR(INDEX(부록3DB!$J$7:$U$1241,MATCH('②-1 기후비작업근거'!$C$6&"|"&4,부록3DB!$I$7:$I$1241,0),10),0) -> 0 | P58: =IFERROR(INDEX(부록3DB!$J$7:$U$1241,MATCH('②-1 기후비작업근거'!$C$6&"|"&4,부록3DB!$I$7:$I$1241,0),11),0) -> 0 | Q58: =IFERROR(INDEX(부록3DB!$J$7:$U$1241,MATCH('②-1 기후비작업근거'!$C$6&"|"&4,부록3DB!$I$7:$I$1241,0),12),0) -> 0 | R58: =SUM(F58:Q58) -> 1.8 | T58: =IFERROR(IF(INDEX('②-1 기후비작업근거'!$F$28:$S$37,MATCH(①공사개요!$C$7,'②-1 기후비작업근거'!$B$28:$B$37,0),4)="Y","Y",""),"")
B59: =IF('②-1 기후비작업근거'!$C$7="자동",$T59,$S59) -> Y | C59: 동절기 | D59: 일최고기온 0℃ 이하 | E59: 한중콘크리트 KCS 14 20 40 | F59: =IFERROR(INDEX(부록3DB!$J$7:$U$1241,MATCH('②-1 기후비작업근거'!$C$6&"|"&5,부록3DB!$I$7:$I$1241,0),1),0) -> 9.9 | G59: =IFERROR(INDEX(부록3DB!$J$7:$U$1241,MATCH('②-1 기후비작업근거'!$C$6&"|"&5,부록3DB!$I$7:$I$1241,0),2),0) -> 4.4 | H59: =IFERROR(INDEX(부록3DB!$J$7:$U$1241,MATCH('②-1 기후비작업근거'!$C$6&"|"&5,부록3DB!$I$7:$I$1241,0),3),0) -> 0.2 | I59: =IFERROR(INDEX(부록3DB!$J$7:$U$1241,MATCH('②-1 기후비작업근거'!$C$6&"|"&5,부록3DB!$I$7:$I$1241,0),4),0) -> 0 | J59: =IFERROR(INDEX(부록3DB!$J$7:$U$1241,MATCH('②-1 기후비작업근거'!$C$6&"|"&5,부록3DB!$I$7:$I$1241,0),5),0) -> 0 | K59: =IFERROR(INDEX(부록3DB!$J$7:$U$1241,MATCH('②-1 기후비작업근거'!$C$6&"|"&5,부록3DB!$I$7:$I$1241,0),6),0) -> 0 | L59: =IFERROR(INDEX(부록3DB!$J$7:$U$1241,MATCH('②-1 기후비작업근거'!$C$6&"|"&5,부록3DB!$I$7:$I$1241,0),7),0) -> 0 | M59: =IFERROR(INDEX(부록3DB!$J$7:$U$1241,MATCH('②-1 기후비작업근거'!$C$6&"|"&5,부록3DB!$I$7:$I$1241,0),8),0) -> 0 | N59: =IFERROR(INDEX(부록3DB!$J$7:$U$1241,MATCH('②-1 기후비작업근거'!$C$6&"|"&5,부록3DB!$I$7:$I$1241,0),9),0) -> 0 | O59: =IFERROR(INDEX(부록3DB!$J$7:$U$1241,MATCH('②-1 기후비작업근거'!$C$6&"|"&5,부록3DB!$I$7:$I$1241,0),10),0) -> 0 | P59: =IFERROR(INDEX(부록3DB!$J$7:$U$1241,MATCH('②-1 기후비작업근거'!$C$6&"|"&5,부록3DB!$I$7:$I$1241,0),11),0) -> 0.5 | Q59: =IFERROR(INDEX(부록3DB!$J$7:$U$1241,MATCH('②-1 기후비작업근거'!$C$6&"|"&5,부록3DB!$I$7:$I$1241,0),12),0) -> 8.3 | R59: =SUM(F59:Q59) -> 23.3 | S59: Y | T59: =IFERROR(IF(INDEX('②-1 기후비작업근거'!$F$28:$S$37,MATCH(①공사개요!$C$7,'②-1 기후비작업근거'!$B$28:$B$37,0),1)="Y","Y",""),"") -> Y
B60: =IF('②-1 기후비작업근거'!$C$7="자동",$T60,$S60) -> Y | C60: 동절기 | D60: 일최심신적설 5㎝ 이상 | E60: 강설 작업제한 | F60: =IFERROR(INDEX(부록3DB!$J$7:$U$1241,MATCH('②-1 기후비작업근거'!$C$6&"|"&6,부록3DB!$I$7:$I$1241,0),1),0) -> 0.1 | G60: =IFERROR(INDEX(부록3DB!$J$7:$U$1241,MATCH('②-1 기후비작업근거'!$C$6&"|"&6,부록3DB!$I$7:$I$1241,0),2),0) -> 0 | H60: =IFERROR(INDEX(부록3DB!$J$7:$U$1241,MATCH('②-1 기후비작업근거'!$C$6&"|"&6,부록3DB!$I$7:$I$1241,0),3),0) -> 0 | I60: =IFERROR(INDEX(부록3DB!$J$7:$U$1241,MATCH('②-1 기후비작업근거'!$C$6&"|"&6,부록3DB!$I$7:$I$1241,0),4),0) -> 0 | J60: =IFERROR(INDEX(부록3DB!$J$7:$U$1241,MATCH('②-1 기후비작업근거'!$C$6&"|"&6,부록3DB!$I$7:$I$1241,0),5),0) -> 0 | K60: =IFERROR(INDEX(부록3DB!$J$7:$U$1241,MATCH('②-1 기후비작업근거'!$C$6&"|"&6,부록3DB!$I$7:$I$1241,0),6),0) -> 0 | L60: =IFERROR(INDEX(부록3DB!$J$7:$U$1241,MATCH('②-1 기후비작업근거'!$C$6&"|"&6,부록3DB!$I$7:$I$1241,0),7),0) -> 0 | M60: =IFERROR(INDEX(부록3DB!$J$7:$U$1241,MATCH('②-1 기후비작업근거'!$C$6&"|"&6,부록3DB!$I$7:$I$1241,0),8),0) -> 0 | N60: =IFERROR(INDEX(부록3DB!$J$7:$U$1241,MATCH('②-1 기후비작업근거'!$C$6&"|"&6,부록3DB!$I$7:$I$1241,0),9),0) -> 0 | O60: =IFERROR(INDEX(부록3DB!$J$7:$U$1241,MATCH('②-1 기후비작업근거'!$C$6&"|"&6,부록3DB!$I$7:$I$1241,0),10),0) -> 0 | P60: =IFERROR(INDEX(부록3DB!$J$7:$U$1241,MATCH('②-1 기후비작업근거'!$C$6&"|"&6,부록3DB!$I$7:$I$1241,0),11),0) -> 0 | Q60: =IFERROR(INDEX(부록3DB!$J$7:$U$1241,MATCH('②-1 기후비작업근거'!$C$6&"|"&6,부록3DB!$I$7:$I$1241,0),12),0) -> 0 | R60: =SUM(F60:Q60) -> 0.1 | S60: Y | T60: =IFERROR(IF(INDEX('②-1 기후비작업근거'!$F$28:$S$37,MATCH(①공사개요!$C$7,'②-1 기후비작업근거'!$B$28:$B$37,0),1)="Y","Y",""),"") -> Y
B61: =IF('②-1 기후비작업근거'!$C$7="자동",$T61,$S61) -> 0 | C61: 동절기 | D61: 일최고 0℃↓ 또는 적설 5㎝↑(결합) | E61: 한중+강설(중복제거) | F61: =IFERROR(INDEX(부록3DB!$J$7:$U$1241,MATCH('②-1 기후비작업근거'!$C$6&"|"&7,부록3DB!$I$7:$I$1241,0),1),0) -> 10 | G61: =IFERROR(INDEX(부록3DB!$J$7:$U$1241,MATCH('②-1 기후비작업근거'!$C$6&"|"&7,부록3DB!$I$7:$I$1241,0),2),0) -> 4.4 | H61: =IFERROR(INDEX(부록3DB!$J$7:$U$1241,MATCH('②-1 기후비작업근거'!$C$6&"|"&7,부록3DB!$I$7:$I$1241,0),3),0) -> 0.2 | I61: =IFERROR(INDEX(부록3DB!$J$7:$U$1241,MATCH('②-1 기후비작업근거'!$C$6&"|"&7,부록3DB!$I$7:$I$1241,0),4),0) -> 0 | J61: =IFERROR(INDEX(부록3DB!$J$7:$U$1241,MATCH('②-1 기후비작업근거'!$C$6&"|"&7,부록3DB!$I$7:$I$1241,0),5),0) -> 0 | K61: =IFERROR(INDEX(부록3DB!$J$7:$U$1241,MATCH('②-1 기후비작업근거'!$C$6&"|"&7,부록3DB!$I$7:$I$1241,0),6),0) -> 0 | L61: =IFERROR(INDEX(부록3DB!$J$7:$U$1241,MATCH('②-1 기후비작업근거'!$C$6&"|"&7,부록3DB!$I$7:$I$1241,0),7),0) -> 0 | M61: =IFERROR(INDEX(부록3DB!$J$7:$U$1241,MATCH('②-1 기후비작업근거'!$C$6&"|"&7,부록3DB!$I$7:$I$1241,0),8),0) -> 0 | N61: =IFERROR(INDEX(부록3DB!$J$7:$U$1241,MATCH('②-1 기후비작업근거'!$C$6&"|"&7,부록3DB!$I$7:$I$1241,0),9),0) -> 0 | O61: =IFERROR(INDEX(부록3DB!$J$7:$U$1241,MATCH('②-1 기후비작업근거'!$C$6&"|"&7,부록3DB!$I$7:$I$1241,0),10),0) -> 0 | P61: =IFERROR(INDEX(부록3DB!$J$7:$U$1241,MATCH('②-1 기후비작업근거'!$C$6&"|"&7,부록3DB!$I$7:$I$1241,0),11),0) -> 0.5 | Q61: =IFERROR(INDEX(부록3DB!$J$7:$U$1241,MATCH('②-1 기후비작업근거'!$C$6&"|"&7,부록3DB!$I$7:$I$1241,0),12),0) -> 8.3 | R61: =SUM(F61:Q61) -> 23.4
...

Sheet ②-2 기후비작업근거
A1: ②-3 기후 비작업일수 산정근거 (부록2 작업제한 기상조건 → 부록3 지역별 통계)
B2: 부록2의 국가건설기준(KCS 등) 작업제한 기상조건을, 부록3 기상청 10년(2015–2024) 지역통계로 일수화하여 월별 기후비작업일수를 산정합니다.
B3: 관측지점을 선택하면 13개 기상조건 값이 부록3에서 자동 반영됩니다. '선택(Y)'한 조건만 합산되며, 미세먼지는 별도 입력값을 사용합니다.
B5: ■ 관측지점 및 공사유형 선택
B6: 관측지점 | C6: =①공사개요!$C$11 -> 철원 | D6: 행정구역 | E6: =①공사개요!$C$6 -> 연천군
B7: 선택방식 | C7: 수동 | D7: 공사유형 | E7: 하수관로
B8: ※ '자동'이면 ①공사개요의 시설유형에 따라 권장 기상조건이 자동 선택(아래 매트릭스 기준). '수동'이면 '수동선택(Y)' 칸으로 직접 지정. 하수도=하수관로 공사 기준 적용.
B10: ■ 부록2 주요 작업제한 기상조건 (해당 공종 선정 참고)
B11: 공종/작업 | C11: 작업제한 기상조건 | E11: 근거
B12: 콘크리트 타설 | C12: 강우·강설 시 원칙 금지 / 동절기 일평균 4℃↓·타설후 24h 일최저 0℃↓ → 한중콘크리트 / 혹서기 일평균 25℃↑·타설후 24h 일최고 30℃↑ → 서중콘크리트 | E12: KCS 14 20 10·40·41
B13: 일반 토공/가시설(관로 굴착) | C13: 강우·강설 시, 동절기 저온 시 작업제한 (하수·상수관로 굴착·관부설 포함) | E13: KCS 11 계열
B14: 양중/타워크레인 | C14: 순간풍속 15m/s↑ 운전중지, 10m/s↑ 설치·해체 중지 | E14: KCS 21 20 10
B15: 강구조 현장용접 | C15: 대기온도 -20℃↓, 강우·강우직후, 풍속 2m/s↑(FCAW) | E15: KCS 14 31 30
B16: 도장/방수/포장 | C16: 5℃ 미만, 강우·강설·강풍 시, 43℃↑ | E16: KCS 14 31 40
B17: 미세먼지(고농도) | C17: PM2.5 '나쁨'(일평균 36㎍/㎥↑)·비상저감조치(50㎍/㎥↑) 시 옥외작업 조정 | E17: 대기관리권역법·지자체 조례
B19: ■ 시설유형별 권장 기상조건 (선택방식='자동' 시 적용) — Y=권장, 셀 수정가능
B20: 시설유형 \ 기상조건 | F20: ①체감33 | G20: ②체감35 | H20: ③최고33 | I20: ④최고35 | J20: ⑤최고0 | K20: ⑥적설5 | L20: ⑦결합 | M20: ⑧최저-12 | N20: ⑨강우3 | O20: ⑩강우5 | P20: ⑪강우10 | Q20: ⑫강우20 | R20: ⑬강풍15 | S20: ⑭미세먼지
B21: 도로포장 | L21: Y | O21: Y | S21: Y
B22: 도로(토공+교량) | F22: Y | L22: Y | P22: Y | R22: Y | S22: Y
B23: 농업용수 | F23: Y | L23: Y | P23: Y | S23: Y
B24: 상수도 | F24: Y | L24: Y | P24: Y | S24: Y
B25: 하수도 | F25: Y | L25: Y | P25: Y | S25: Y
B26: 철도(궤도) | F26: Y | L26: Y | P26: Y | R26: Y | S26: Y
B27: 학교 | F27: Y | L27: Y | O27: Y | R27: Y | S27: Y
B28: 청사 | F28: Y | L28: Y | O28: Y | R28: Y | S28: Y
B29: 기타건축물 | F29: Y | L29: Y | O29: Y | R29: Y | S29: Y
B30: 기타 | F30: Y | L30: Y | O30: Y | R30: Y | S30: Y
B31: ※ 하수도=하수관로(토공·관부설) 기준 → 혹서기 폭염(체감33)·동절기 결합·강우10㎜·미세먼지 권장. 구조물(학교·청사 등)은 강우5㎜·강풍 포함. 셀의 Y/공백을 수정하면 권장이 바뀝니다.
B55: ■ 기상조건별 비작업일수 (선택지점 자동조회, 2015–2024 월평균) — 선택=위 방식(자동:권장/수동:수동선택)
B56: 선택 | C56: 구분 | D56: 기상조건 | E56: 근거/기준 | F56: 1월 | G56: 2월 | H56: 3월 | I56: 4월 | J56: 5월 | K56: 6월 | L56: 7월 | M56: 8월 | N56: 9월 | O56: 10월 | P56: 11월 | Q56: 12월 | R56: 소계 | S56: 수동선택 | T56: 권장
B57: =IF('②-2 기후비작업근거'!$C$7="자동",$T57,$S57) -> 0 | C57: 혹서기 | D57: 체감온도 33℃ 이상 | E57: 서중콘크리트/폭염 KCS 14 20 41 | F57: =IFERROR(INDEX(부록3DB!$J$7:$U$1241,MATCH('②-2 기후비작업근거'!$C$6&"|"&1,부록3DB!$I$7:$I$1241,0),1),0) -> 0 | G57: =IFERROR(INDEX(부록3DB!$J$7:$U$1241,MATCH('②-2 기후비작업근거'!$C$6&"|"&1,부록3DB!$I$7:$I$1241,0),2),0) -> 0 | H57: =IFERROR(INDEX(부록3DB!$J$7:$U$1241,MATCH('②-2 기후비작업근거'!$C$6&"|"&1,부록3DB!$I$7:$I$1241,0),3),0) -> 0 | I57: =IFERROR(INDEX(부록3DB!$J$7:$U$1241,MATCH('②-2 기후비작업근거'!$C$6&"|"&1,부록3DB!$I$7:$I$1241,0),4),0) -> 0 | J57: =IFERROR(INDEX(부록3DB!$J$7:$U$1241,MATCH('②-2 기후비작업근거'!$C$6&"|"&1,부록3DB!$I$7:$I$1241,0),5),0) -> 0 | K57: =IFERROR(INDEX(부록3DB!$J$7:$U$1241,MATCH('②-2 기후비작업근거'!$C$6&"|"&1,부록3DB!$I$7:$I$1241,0),6),0) -> 0 | L57: =IFERROR(INDEX(부록3DB!$J$7:$U$1241,MATCH('②-2 기후비작업근거'!$C$6&"|"&1,부록3DB!$I$7:$I$1241,0),7),0) -> 5.7 | M57: =IFERROR(INDEX(부록3DB!$J$7:$U$1241,MATCH('②-2 기후비작업근거'!$C$6&"|"&1,부록3DB!$I$7:$I$1241,0),8),0) -> 9.2 | N57: =IFERROR(INDEX(부록3DB!$J$7:$U$1241,MATCH('②-2 기후비작업근거'!$C$6&"|"&1,부록3DB!$I$7:$I$1241,0),9),0) -> 0.1 | O57: =IFERROR(INDEX(부록3DB!$J$7:$U$1241,MATCH('②-2 기후비작업근거'!$C$6&"|"&1,부록3DB!$I$7:$I$1241,0),10),0) -> 0 | P57: =IFERROR(INDEX(부록3DB!$J$7:$U$1241,MATCH('②-2 기후비작업근거'!$C$6&"|"&1,부록3DB!$I$7:$I$1241,0),11),0) -> 0 | Q57: =IFERROR(INDEX(부록3DB!$J$7:$U$1241,MATCH('②-2 기후비작업근거'!$C$6&"|"&1,부록3DB!$I$7:$I$1241,0),12),0) -> 0 | R57: =SUM(F57:Q57) -> 15
B58: =IF('②-2 기후비작업근거'!$C$7="자동",$T58,$S58) -> 0 | C58: 혹서기 | D58: 체감온도 35℃ 이상 | E58: 폭염경보 기준 | F58: =IFERROR(INDEX(부록3DB!$J$7:$U$1241,MATCH('②-2 기후비작업근거'!$C$6&"|"&2,부록3DB!$I$7:$I$1241,0),1),0) -> 0 | G58: =IFERROR(INDEX(부록3DB!$J$7:$U$1241,MATCH('②-2 기후비작업근거'!$C$6&"|"&2,부록3DB!$I$7:$I$1241,0),2),0) -> 0 | H58: =IFERROR(INDEX(부록3DB!$J$7:$U$1241,MATCH('②-2 기후비작업근거'!$C$6&"|"&2,부록3DB!$I$7:$I$1241,0),3),0) -> 0 | I58: =IFERROR(INDEX(부록3DB!$J$7:$U$1241,MATCH('②-2 기후비작업근거'!$C$6&"|"&2,부록3DB!$I$7:$I$1241,0),4),0) -> 0 | J58: =IFERROR(INDEX(부록3DB!$J$7:$U$1241,MATCH('②-2 기후비작업근거'!$C$6&"|"&2,부록3DB!$I$7:$I$1241,0),5),0) -> 0 | K58: =IFERROR(INDEX(부록3DB!$J$7:$U$1241,MATCH('②-2 기후비작업근거'!$C$6&"|"&2,부록3DB!$I$7:$I$1241,0),6),0) -> 0 | L58: =IFERROR(INDEX(부록3DB!$J$7:$U$1241,MATCH('②-2 기후비작업근거'!$C$6&"|"&2,부록3DB!$I$7:$I$1241,0),7),0) -> 0.9 | M58: =IFERROR(INDEX(부록3DB!$J$7:$U$1241,MATCH('②-2 기후비작업근거'!$C$6&"|"&2,부록3DB!$I$7:$I$1241,0),8),0) -> 1.8 | N58: =IFERROR(INDEX(부록3DB!$J$7:$U$1241,MATCH('②-2 기후비작업근거'!$C$6&"|"&2,부록3DB!$I$7:$I$1241,0),9),0) -> 0 | O58: =IFERROR(INDEX(부록3DB!$J$7:$U$1241,MATCH('②-2 기후비작업근거'!$C$6&"|"&2,부록3DB!$I$7:$I$1241,0),10),0) -> 0 | P58: =IFERROR(INDEX(부록3DB!$J$7:$U$1241,MATCH('②-2 기후비작업근거'!$C$6&"|"&2,부록3DB!$I$7:$I$1241,0),11),0) -> 0 | Q58: =IFERROR(INDEX(부록3DB!$J$7:$U$1241,MATCH('②-2 기후비작업근거'!$C$6&"|"&2,부록3DB!$I$7:$I$1241,0),12),0) -> 0 | R58: =SUM(F58:Q58) -> 2.7 | T58: =IFERROR(IF(INDEX('②-2 기후비작업근거'!$F$21:$S$30,MATCH(①공사개요!$C$7,'②-2 기후비작업근거'!$B$21:$B$30,0),2)="Y","Y",""),"")
B59: =IF('②-2 기후비작업근거'!$C$7="자동",$T59,$S59) -> 0 | C59: 혹서기 | D59: 일최고온도 33℃ 이상 | E59: 서중콘크리트 참고 | F59: =IFERROR(INDEX(부록3DB!$J$7:$U$1241,MATCH('②-2 기후비작업근거'!$C$6&"|"&3,부록3DB!$I$7:$I$1241,0),1),0) -> 0 | G59: =IFERROR(INDEX(부록3DB!$J$7:$U$1241,MATCH('②-2 기후비작업근거'!$C$6&"|"&3,부록3DB!$I$7:$I$1241,0),2),0) -> 0 | H59: =IFERROR(INDEX(부록3DB!$J$7:$U$1241,MATCH('②-2 기후비작업근거'!$C$6&"|"&3,부록3DB!$I$7:$I$1241,0),3),0) -> 0 | I59: =IFERROR(INDEX(부록3DB!$J$7:$U$1241,MATCH('②-2 기후비작업근거'!$C$6&"|"&3,부록3DB!$I$7:$I$1241,0),4),0) -> 0 | J59: =IFERROR(INDEX(부록3DB!$J$7:$U$1241,MATCH('②-2 기후비작업근거'!$C$6&"|"&3,부록3DB!$I$7:$I$1241,0),5),0) -> 0 | K59: =IFERROR(INDEX(부록3DB!$J$7:$U$1241,MATCH('②-2 기후비작업근거'!$C$6&"|"&3,부록3DB!$I$7:$I$1241,0),6),0) -> 0.7 | L59: =IFERROR(INDEX(부록3DB!$J$7:$U$1241,MATCH('②-2 기후비작업근거'!$C$6&"|"&3,부록3DB!$I$7:$I$1241,0),7),0) -> 3.7 | M59: =IFERROR(INDEX(부록3DB!$J$7:$U$1241,MATCH('②-2 기후비작업근거'!$C$6&"|"&3,부록3DB!$I$7:$I$1241,0),8),0) -> 6 | N59: =IFERROR(INDEX(부록3DB!$J$7:$U$1241,MATCH('②-2 기후비작업근거'!$C$6&"|"&3,부록3DB!$I$7:$I$1241,0),9),0) -> 0.1 | O59: =IFERROR(INDEX(부록3DB!$J$7:$U$1241,MATCH('②-2 기후비작업근거'!$C$6&"|"&3,부록3DB!$I$7:$I$1241,0),10),0) -> 0 | P59: =IFERROR(INDEX(부록3DB!$J$7:$U$1241,MATCH('②-2 기후비작업근거'!$C$6&"|"&3,부록3DB!$I$7:$I$1241,0),11),0) -> 0 | Q59: =IFERROR(INDEX(부록3DB!$J$7:$U$1241,MATCH('②-2 기후비작업근거'!$C$6&"|"&3,부록3DB!$I$7:$I$1241,0),12),0) -> 0 | R59: =SUM(F59:Q59) -> 10.5 | T59: =IFERROR(IF(INDEX('②-2 기후비작업근거'!$F$21:$S$30,MATCH(①공사개요!$C$7,'②-2 기후비작업근거'!$B$21:$B$30,0),3)="Y","Y",""),"")
B60: =IF('②-2 기후비작업근거'!$C$7="자동",$T60,$S60) -> Y | C60: 혹서기 | D60: 일최고온도 35℃ 이상 | E60: 폭염특보 | F60: =IFERROR(INDEX(부록3DB!$J$7:$U$1241,MATCH('②-2 기후비작업근거'!$C$6&"|"&4,부록3DB!$I$7:$I$1241,0),1),0) -> 0 | G60: =IFERROR(INDEX(부록3DB!$J$7:$U$1241,MATCH('②-2 기후비작업근거'!$C$6&"|"&4,부록3DB!$I$7:$I$1241,0),2),0) -> 0 | H60: =IFERROR(INDEX(부록3DB!$J$7:$U$1241,MATCH('②-2 기후비작업근거'!$C$6&"|"&4,부록3DB!$I$7:$I$1241,0),3),0) -> 0 | I60: =IFERROR(INDEX(부록3DB!$J$7:$U$1241,MATCH('②-2 기후비작업근거'!$C$6&"|"&4,부록3DB!$I$7:$I$1241,0),4),0) -> 0 | J60: =IFERROR(INDEX(부록3DB!$J$7:$U$1241,MATCH('②-2 기후비작업근거'!$C$6&"|"&4,부록3DB!$I$7:$I$1241,0),5),0) -> 0 | K60: =IFERROR(INDEX(부록3DB!$J$7:$U$1241,MATCH('②-2 기후비작업근거'!$C$6&"|"&4,부록3DB!$I$7:$I$1241,0),6),0) -> 0.1 | L60: =IFERROR(INDEX(부록3DB!$J$7:$U$1241,MATCH('②-2 기후비작업근거'!$C$6&"|"&4,부록3DB!$I$7:$I$1241,0),7),0) -> 0.9 | M60: =IFERROR(INDEX(부록3DB!$J$7:$U$1241,MATCH('②-2 기후비작업근거'!$C$6&"|"&4,부록3DB!$I$7:$I$1241,0),8),0) -> 0.8 | N60: =IFERROR(INDEX(부록3DB!$J$7:$U$1241,MATCH('②-2 기후비작업근거'!$C$6&"|"&4,부록3DB!$I$7:$I$1241,0),9),0) -> 0 | O60: =IFERROR(INDEX(부록3DB!$J$7:$U$1241,MATCH('②-2 기후비작업근거'!$C$6&"|"&4,부록3DB!$I$7:$I$1241,0),10),0) -> 0 | P60: =IFERROR(INDEX(부록3DB!$J$7:$U$1241,MATCH('②-2 기후비작업근거'!$C$6&"|"&4,부록3DB!$I$7:$I$1241,0),11),0) -> 0 | Q60: =IFERROR(INDEX(부록3DB!$J$7:$U$1241,MATCH('②-2 기후비작업근거'!$C$6&"|"&4,부록3DB!$I$7:$I$1241,0),12),0) -> 0 | R60: =SUM(F60:Q60) -> 1.8 | S60: Y | T60: =IFERROR(IF(INDEX('②-2 기후비작업근거'!$F$21:$S$30,MATCH(①공사개요!$C$7,'②-2 기후비작업근거'!$B$21:$B$30,0),1)="Y","Y",""),"") -> Y
B61: =IF('②-2 기후비작업근거'!$C$7="자동",$T61,$S61) -> 0 | C61: 동절기 | D61: 일최고기온 0℃ 이하 | E61: 한중콘크리트 KCS 14 20 40 | F61: =IFERROR(INDEX(부록3DB!$J$7:$U$1241,MATCH('②-2 기후비작업근거'!$C$6&"|"&5,부록3DB!$I$7:$I$1241,0),1),0) -> 9.9 | G61: =IFERROR(INDEX(부록3DB!$J$7:$U$1241,MATCH('②-2 기후비작업근거'!$C$6&"|"&5,부록3DB!$I$7:$I$1241,0),2),0) -> 4.4 | H61: =IFERROR(INDEX(부록3DB!$J$7:$U$1241,MATCH('②-2 기후비작업근거'!$C$6&"|"&5,부록3DB!$I$7:$I$1241,0),3),0) -> 0.2 | I61: =IFERROR(INDEX(부록3DB!$J$7:$U$1241,MATCH('②-2 기후비작업근거'!$C$6&"|"&5,부록3DB!$I$7:$I$1241,0),4),0) -> 0 | J61: =IFERROR(INDEX(부록3DB!$J$7:$U$1241,MATCH('②-2 기후비작업근거'!$C$6&"|"&5,부록3DB!$I$7:$I$1241,0),5),0) -> 0 | K61: =IFERROR(INDEX(부록3DB!$J$7:$U$1241,MATCH('②-2 기후비작업근거'!$C$6&"|"&5,부록3DB!$I$7:$I$1241,0),6),0) -> 0 | L61: =IFERROR(INDEX(부록3DB!$J$7:$U$1241,MATCH('②-2 기후비작업근거'!$C$6&"|"&5,부록3DB!$I$7:$I$1241,0),7),0) -> 0 | M61: =IFERROR(INDEX(부록3DB!$J$7:$U$1241,MATCH('②-2 기후비작업근거'!$C$6&"|"&5,부록3DB!$I$7:$I$1241,0),8),0) -> 0 | N61: =IFERROR(INDEX(부록3DB!$J$7:$U$1241,MATCH('②-2 기후비작업근거'!$C$6&"|"&5,부록3DB!$I$7:$I$1241,0),9),0) -> 0 | O61: =IFERROR(INDEX(부록3DB!$J$7:$U$1241,MATCH('②-2 기후비작업근거'!$C$6&"|"&5,부록3DB!$I$7:$I$1241,0),10),0) -> 0 | P61: =IFERROR(INDEX(부록3DB!$J$7:$U$1241,MATCH('②-2 기후비작업근거'!$C$6&"|"&5,부록3DB!$I$7:$I$1241,0),11),0) -> 0.5 | Q61: =IFERROR(INDEX(부록3DB!$J$7:$U$1241,MATCH('②-2 기후비작업근거'!$C$6&"|"&5,부록3DB!$I$7:$I$1241,0),12),0) -> 8.3 | R61: =SUM(F61:Q61) -> 23.3 | T61: =IFERROR(IF(INDEX('②-2 기후비작업근거'!$F$21:$S$30,MATCH(①공사개요!$C$7,'②-2 기후비작업근거'!$B$21:$B$30,0),5)="Y","Y",""),"")
B62: =IF('②-2 기후비작업근거'!$C$7="자동",$T62,$S62) -> 0 | C62: 동절기 | D62: 일최심신적설 5㎝ 이상 | E62: 강설 작업제한 | F62: =IFERROR(INDEX(부록3DB!$J$7:$U$1241,MATCH('②-2 기후비작업근거'!$C$6&"|"&6,부록3DB!$I$7:$I$1241,0),1),0) -> 0.1 | G62: =IFERROR(INDEX(부록3DB!$J$7:$U$1241,MATCH('②-2 기후비작업근거'!$C$6&"|"&6,부록3DB!$I$7:$I$1241,0),2),0) -> 0 | H62: =IFERROR(INDEX(부록3DB!$J$7:$U$1241,MATCH('②-2 기후비작업근거'!$C$6&"|"&6,부록3DB!$I$7:$I$1241,0),3),0) -> 0 | I62: =IFERROR(INDEX(부록3DB!$J$7:$U$1241,MATCH('②-2 기후비작업근거'!$C$6&"|"&6,부록3DB!$I$7:$I$1241,0),4),0) -> 0 | J62: =IFERROR(INDEX(부록3DB!$J$7:$U$1241,MATCH('②-2 기후비작업근거'!$C$6&"|"&6,부록3DB!$I$7:$I$1241,0),5),0) -> 0 | K62: =IFERROR(INDEX(부록3DB!$J$7:$U$1241,MATCH('②-2 기후비작업근거'!$C$6&"|"&6,부록3DB!$I$7:$I$1241,0),6),0) -> 0 | L62: =IFERROR(INDEX(부록3DB!$J$7:$U$1241,MATCH('②-2 기후비작업근거'!$C$6&"|"&6,부록3DB!$I$7:$I$1241,0),7),0) -> 0 | M62: =IFERROR(INDEX(부록3DB!$J$7:$U$1241,MATCH('②-2 기후비작업근거'!$C$6&"|"&6,부록3DB!$I$7:$I$1241,0),8),0) -> 0 | N62: =IFERROR(INDEX(부록3DB!$J$7:$U$1241,MATCH('②-2 기후비작업근거'!$C$6&"|"&6,부록3DB!$I$7:$I$1241,0),9),0) -> 0 | O62: =IFERROR(INDEX(부록3DB!$J$7:$U$1241,MATCH('②-2 기후비작업근거'!$C$6&"|"&6,부록3DB!$I$7:$I$1241,0),10),0) -> 0 | P62: =IFERROR(INDEX(부록3DB!$J$7:$U$1241,MATCH('②-2 기후비작업근거'!$C$6&"|"&6,부록3DB!$I$7:$I$1241,0),11),0) -> 0 | Q62: =IFERROR(INDEX(부록3DB!$J$7:$U$1241,MATCH('②-2 기후비작업근거'!$C$6&"|"&6,부록3DB!$I$7:$I$1241,0),12),0) -> 0 | R62: =SUM(F62:Q62) -> 0.1 | T62: =IFERROR(IF(INDEX('②-2 기후비작업근거'!$F$21:$S$30,MATCH(①공사개요!$C$7,'②-2 기후비작업근거'!$B$21:$B$30,0),6)="Y","Y",""),"")
B63: =IF('②-2 기후비작업근거'!$C$7="자동",$T63,$S63) -> 0 | C63: 동절기 | D63: 일최고 0℃↓ 또는 적설 5㎝↑(결합) | E63: 한중+강설(중복제거) | F63: =IFERROR(INDEX(부록3DB!$J$7:$U$1241,MATCH('②-2 기후비작업근거'!$C$6&"|"&7,부록3DB!$I$7:$I$1241,0),1),0) -> 10 | G63: =IFERROR(INDEX(부록3DB!$J$7:$U$1241,MATCH('②-2 기후비작업근거'!$C$6&"|"&7,부록3DB!$I$7:$I$1241,0),2),0) -> 4.4 | H63: =IFERROR(INDEX(부록3DB!$J$7:$U$1241,MATCH('②-2 기후비작업근거'!$C$6&"|"&7,부록3DB!$I$7:$I$1241,0),3),0) -> 0.2 | I63: =IFERROR(INDEX(부록3DB!$J$7:$U$1241,MATCH('②-2 기후비작업근거'!$C$6&"|"&7,부록3DB!$I$7:$I$1241,0),4),0) -> 0 | J63: =IFERROR(INDEX(부록3DB!$J$7:$U$1241,MATCH('②-2 기후비작업근거'!$C$6&"|"&7,부록3DB!$I$7:$I$1241,0),5),0) -> 0 | K63: =IFERROR(INDEX(부록3DB!$J$7:$U$1241,MATCH('②-2 기후비작업근거'!$C$6&"|"&7,부록3DB!$I$7:$I$1241,0),6),0) -> 0 | L63: =IFERROR(INDEX(부록3DB!$J$7:$U$1241,MATCH('②-2 기후비작업근거'!$C$6&"|"&7,부록3DB!$I$7:$I$1241,0),7),0) -> 0 | M63: =IFERROR(INDEX(부록3DB!$J$7:$U$1241,MATCH('②-2 기후비작업근거'!$C$6&"|"&7,부록3DB!$I$7:$I$1241,0),8),0) -> 0 | N63: =IFERROR(INDEX(부록3DB!$J$7:$U$1241,MATCH('②-2 기후비작업근거'!$C$6&"|"&7,부록3DB!$I$7:$I$1241,0),9),0) -> 0 | O63: =IFERROR(INDEX(부록3DB!$J$7:$U$1241,MATCH('②-2 기후비작업근거'!$C$6&"|"&7,부록3DB!$I$7:$I$1241,0),10),0) -> 0 | P63: =IFERROR(INDEX(부록3DB!$J$7:$U$1241,MATCH('②-2 기후비작업근거'!$C$6&"|"&7,부록3DB!$I$7:$I$1241,0),11),0) -> 0.5 | Q63: =IFERROR(INDEX(부록3DB!$J$7:$U$1241,MATCH('②-2 기후비작업근거'!$C$6&"|"&7,부록3DB!$I$7:$I$1241,0),12),0) -> 8.3 | R63: =SUM(F63:Q63) -> 23.4
B64: =IF('②-2 기후비작업근거'!$C$7="자동",$T64,$S64) -> 0 | C64: 동절기 | D64: 일최저기온 -12℃ 이하 | E64: 혹한 작업중지 | F64: =IFERROR(INDEX(부록3DB!$J$7:$U$1241,MATCH('②-2 기후비작업근거'!$C$6&"|"&8,부록3DB!$I$7:$I$1241,0),1),0) -> 14.3 | G64: =IFERROR(INDEX(부록3DB!$J$7:$U$1241,MATCH('②-2 기후비작업근거'!$C$6&"|"&8,부록3DB!$I$7:$I$1241,0),2),0) -> 6 | H64: =IFERROR(INDEX(부록3DB!$J$7:$U$1241,MATCH('②-2 기후비작업근거'!$C$6&"|"&8,부록3DB!$I$7:$I$1241,0),3),0) -> 0.1 | I64: =IFERROR(INDEX(부록3DB!$J$7:$U$1241,MATCH('②-2 기후비작업근거'!$C$6&"|"&8,부록3DB!$I$7:$I$1241,0),4),0) -> 0 | J64: =IFERROR(INDEX(부록3DB!$J$7:$U$1241,MATCH('②-2 기후비작업근거'!$C$6&"|"&8,부록3DB!$I$7:$I$1241,0),5),0) -> 0 | K64: =IFERROR(INDEX(부록3DB!$J$7:$U$1241,MATCH('②-2 기후비작업근거'!$C$6&"|"&8,부록3DB!$I$7:$I$1241,0),6),0) -> 0 | L64: =IFERROR(INDEX(부록3DB!$J$7:$U$1241,MATCH('②-2 기후비작업근거'!$C$6&"|"&8,부록3DB!$I$7:$I$1241,0),7),0) -> 0 | M64: =IFERROR(INDEX(부록3DB!$J$7:$U$1241,MATCH('②-2 기후비작업근거'!$C$6&"|"&8,부록3DB!$I$7:$I$1241,0),8),0) -> 0 | N64: =IFERROR(INDEX(부록3DB!$J$7:$U$1241,MATCH('②-2 기후비작업근거'!$C$6&"|"&8,부록3DB!$I$7:$I$1241,0),9),0) -> 0 | O64: =IFERROR(INDEX(부록3DB!$J$7:$U$1241,MATCH('②-2 기후비작업근거'!$C$6&"|"&8,부록3DB!$I$7:$I$1241,0),10),0) -> 0 | P64: =IFERROR(INDEX(부록3DB!$J$7:$U$1241,MATCH('②-2 기후비작업근거'!$C$6&"|"&8,부록3DB!$I$7:$I$1241,0),11),0) -> 0 | Q64: =IFERROR(INDEX(부록3DB!$J$7:$U$1241,MATCH('②-2 기후비작업근거'!$C$6&"|"&8,부록3DB!$I$7:$I$1241,0),12),0) -> 8.7 | R64: =SUM(F64:Q64) -> 29.1 | T64: =IFERROR(IF(INDEX('②-2 기후비작업근거'!$F$21:$S$30,MATCH(①공사개요!$C$7,'②-2 기후비작업근거'!$B$21:$B$30,0),8)="Y","Y",""),"")
B65: =IF('②-2 기후비작업근거'!$C$7="자동",$T65,$S65) -> Y | C65: 동절기 | D65: 일최고 5℃ 이하 | F65: 15.6 | G65: 7.4 | H65: 0.4 | I65: - | J65: - | K65: - | L65: - | M65: - | N65: - | O65: - | P65: 0.8 | Q65: 12.7 | R65: =SUM(F65:Q65) -> 36.9 | S65: Y | T65: =IFERROR(IF(INDEX('②-2 기후비작업근거'!$F$21:$S$30,MATCH(①공사개요!$C$7,'②-2 기후비작업근거'!$B$21:$B$30,0),11)="Y","Y",""),"") -> Y
B66: =IF('②-2 기후비작업근거'!$C$7="자동",$T66,$S66) -> Y | C66: 강우 | D66: 일강수량 3㎜ 이상 | E66: 강우 타설금지(보수적) | F66: =IFERROR(INDEX(부록3DB!$J$7:$U$1241,MATCH('②-2 기후비작업근거'!$C$6&"|"&9,부록3DB!$I$7:$I$1241,0),1),0) -> 1.1 | G66: =IFERROR(INDEX(부록3DB!$J$7:$U$1241,MATCH('②-2 기후비작업근거'!$C$6&"|"&9,부록3DB!$I$7:$I$1241,0),2),0) -> 2 | H66: =IFERROR(INDEX(부록3DB!$J$7:$U$1241,MATCH('②-2 기후비작업근거'!$C$6&"|"&9,부록3DB!$I$7:$I$1241,0),3),0) -> 2.6 | I66: =IFERROR(INDEX(부록3DB!$J$7:$U$1241,MATCH('②-2 기후비작업근거'!$C$6&"|"&9,부록3DB!$I$7:$I$1241,0),4),0) -> 4.3 | J66: =IFERROR(INDEX(부록3DB!$J$7:$U$1241,MATCH('②-2 기후비작업근거'!$C$6&"|"&9,부록3DB!$I$7:$I$1241,0),5),0) -> 5.5 | K66: =IFERROR(INDEX(부록3DB!$J$7:$U$1241,MATCH('②-2 기후비작업근거'!$C$6&"|"&9,부록3DB!$I$7:$I$1241,0),6),0) -> 5.7 | L66: =IFERROR(INDEX(부록3DB!$J$7:$U$1241,MATCH('②-2 기후비작업근거'!$C$6&"|"&9,부록3DB!$I$7:$I$1241,0),7),0) -> 10.4 | M66: =IFERROR(INDEX(부록3DB!$J$7:$U$1241,MATCH('②-2 기후비작업근거'!$C$6&"|"&9,부록3DB!$I$7:$I$1241,0),8),0) -> 8.4 | N66: =IFERROR(INDEX(부록3DB!$J$7:$U$1241,MATCH('②-2 기후비작업근거'!$C$6&"|"&9,부록3DB!$I$7:$I$1241,0),9),0) -> 4.5 | O66: =IFERROR(INDEX(부록3DB!$J$7:$U$1241,MATCH('②-2 기후비작업근거'!$C$6&"|"&9,부록3DB!$I$7:$I$1241,0),10),0) -> 3.6 | P66: =IFERROR(INDEX(부록3DB!$J$7:$U$1241,MATCH('②-2 기후비작업근거'!$C$6&"|"&9,부록3DB!$I$7:$I$1241,0),11),0) -> 4.3 | Q66: =IFERROR(INDEX(부록3DB!$J$7:$U$1241,MATCH('②-2 기후비작업근거'!$C$6&"|"&9,부록3DB!$I$7:$I$1241,0),12),0) -> 1.7 | R66: =SUM(F66:Q66) -> 54.1 | S66: Y | T66: =IFERROR(IF(INDEX('②-2 기후비작업근거'!$F$21:$S$30,MATCH(①공사개요!$C$7,'②-2 기후비작업근거'!$B$21:$B$30,0),11)="Y","Y",""),"") -> Y
...

Sheet ③1일작업량DB
A1: ③ 1일 작업량 DB (부록4) — ④작업일수산정에서 자동 조회
B2: 부록4: 대표·일반화된 공종/공법, 표준품셈 생산성(1개 작업조 투입) 기준. 현장여건 고려하여 조정 적용.
B3: ※ '키' = 대공정 + 세부공종 (④에서 이 키로 1일작업량을 조회). 부록4에 없는 공종은 ④에서 직접입력.
B5: No | C5: 분야 | D5: 대공정 | E5: 세부공종(키) | F5: 작업조건/산출근거 | G5: 1일작업량 | H5: 단위 | J5: 조회키
B6: 1 | C6: 토목 | D6: 공통가설 | E6: 가설사무실 | F6: - | G6: 0.143 | H6: 개소/일 | J6: =D6&"|"&E6 -> 공통가설|가설사무실
B7: 2 | C7: 토목 | D7: 공통가설 | E7: 가설울타리 | F7: H형강지주 4m 이하 | G7: 30 | H7: m/일 | J7: =D7&"|"&E7 -> 공통가설|가설울타리
B8: 3 | C8: 토목 | D8: 공통가설 | E8: 가설방음벽 | F8: H형강지주 4m 이하 | G8: 30 | H8: m/일 | J8: =D8&"|"&E8 -> 공통가설|가설방음벽
B9: 4 | C9: 토목 | D9: 공통가설 | E9: 구조물 동바리 | F9: 시스템동바리 30m 이하 | G9: 82 | H9: ㎥/일 | J9: =D9&"|"&E9 -> 공통가설|구조물 동바리
B10: 5 | C10: 토목 | D10: 공통가설 | E10: 구조물 비계 | F10: 강관비계 30m 이하 | G10: 102 | H10: ㎡/일 | J10: =D10&"|"&E10 -> 공통가설|구조물 비계
B11: 6 | C11: 토목 | D11: 공통가설 | E11: 가설흙막이(H파일) | F11: 진동파일해머, 근입장20m | G11: 8 | H11: 본/일 | J11: =D11&"|"&E11 -> 공통가설|가설흙막이(H파일)
B12: 7 | C12: 토목 | D12: 공통가설 | E12: 가설흙막이(강널말뚝) | F12: 진동파일해머, 근입장20m | G12: 10 | H12: 본/일 | J12: =D12&"|"&E12 -> 공통가설|가설흙막이(강널말뚝)
B13: 8 | C13: 토목 | D13: 공통가설 | E13: 가설흙막이(워터제트) | F13: 강널말뚝, 근입장20m | G13: 6 | H13: 본/일 | J13: =D13&"|"&E13 -> 공통가설|가설흙막이(워터제트)
B14: 9 | C14: 토목 | D14: 토공 | E14: 기존시설물 깨기 | F14: 아스콘 t=30㎝ 이상 | G14: 54 | H14: ㎥/일 | J14: =D14&"|"&E14 -> 토공|기존시설물 깨기
B15: 10 | C15: 토목 | D15: 토공 | E15: 벌목 | F15: 벌목 8m 이상 | G15: 1375 | H15: ㎡/일 | J15: =D15&"|"&E15 -> 토공|벌목
B16: 11 | C16: 토목 | D16: 토공 | E16: 벌개제근 | F16: - | G16: 1110 | H16: ㎡/일 | J16: =D16&"|"&E16 -> 토공|벌개제근
B17: 12 | C17: 토목 | D17: 토공 | E17: 표토제거 | F17: 답구간 | G17: 1915 | H17: ㎡/일 | J17: =D17&"|"&E17 -> 토공|표토제거
... B169: 164 | C169: 토목 | D169: 부대공 | E169: 수압·수밀시험 | F169: D50~250 | G169: 3 | H169: 개소/일 | J169: =D169&"|"&E169 -> 부대공|수압·수밀시험

Sheet ④작업일수산정
A1: ④ 작업일수 산정 (수량집계 → 1일작업량 → 작업일수) ※ 대공정·단위작업·소단위작업 3단계
B2: 순작업일수 = ROUNDUP( 작업수량 ÷ (적용1일작업량 × 작업조수) ). 출처='부록4'면 1일작업량 자동조회 / '품셈·실적'이면 수동1일작업량 칸에 입력. 소단위작업까지 분할하면 ⑤에서 선행·중첩이 뚜렷해집니다.
B4: No | C4: 대공정 | D4: 단위작업(세부공종) | E4: 소단위작업 | F4: 출처 | G4: 작업수량 | H4: 단위 | I4: 수동1일작업량 (품셈/실적) | J4: 적용1일작업량 | K4: 작업 조수 | L4: 순작업 일수 | M4: 간접 작업일수 | N4: 보정 일수 | O4: 총작업일수 | R4: =⑥공사기간종합!C10 -> 0
C5: 빗물펌프장 | O5: =SUM(O6:O55) -> 527.5
B6: 1 | C6: 토공 | D6: 토사굴착(1.0㎥,지장물) | E6: 기계터파기/보통토사/5m이하 | F6: 부록4 | G6: 8914 | H6: =IF($F6="부록4",IFERROR(INDEX(③1일작업량DB!$H$6:$H$112,MATCH($C6&"|"&$D6,③1일작업량DB!$J$6:$J$112,0)),"-"),"") -> ㎥/일 | J6: =IF($F6="부록4",IFERROR(INDEX(③1일작업량DB!$G$6:$G$112,MATCH($C6&"|"&$D6,③1일작업량DB!$J$6:$J$112,0)),""),$I6) -> 380 | K6: 3 | L6: =IFERROR(IF(AND($G6>0,$J6>0,$K6>0),ROUNDUP($G6/($J6*$K6),1),0),0) -> 7.9 | M6: 0 | N6: 0 | O6: =$L6+$M6+$N6 -> 7.9
B7: =B6+1 -> 2 | C7: 토공 | D7: 토사굴착(1.0㎥,지장물) | E7: 기계터파기/보통토사/5m초과 | F7: 부록4 | G7: 9754 | H7: =IF($F7="부록4",IFERROR(INDEX(③1일작업량DB!$H$6:$H$112,MATCH($C7&"|"&$D7,③1일작업량DB!$J$6:$J$112,0)),"-"),"") -> ㎥/일 | J7: =IF($F7="부록4",IFERROR(INDEX(③1일작업량DB!$G$6:$G$112,MATCH($C7&"|"&$D7,③1일작업량DB!$J$6:$J$112,0)),""),$I7) -> 380 | K7: 3 | L7: =IFERROR(IF(AND($G7>0,$J7>0,$K7>0),ROUNDUP($G7/($J7*$K7),1),0),0) -> 8.6 | M7: 0 | N7: 0 | O7: =$L7+$M7+$N7 -> 8.6
B8: =B7+1 -> 3 | C8: 토공 | D8: 토사굴착(1.0㎥,지장물) | E8: 터파기/보통토사/5m이하 | F8: 부록4 | G8: 173 | H8: =IF($F8="부록4",IFERROR(INDEX(③1일작업량DB!$H$6:$H$112,MATCH($C8&"|"&$D8,③1일작업량DB!$J$6:$J$112,0)),"-"),"") -> ㎥/일 | J8: 514 | K8: 3 | L8: =IFERROR(IF(AND($G8>0,$J8>0,$K8>0),ROUNDUP($G8/($J8*$K8),1),0),0) -> 0.2 | M8: 0 | N8: 0 | O8: =$L8+$M8+$N8 -> 0.2
B9: =B8+1 -> 4 | C9: 토공 | D9: 되메우기 | E9: 되메우기 및 다짐 | F9: 부록4 | G9: =4384+92+2+1 -> 4479 | H9: =IF($F9="부록4",IFERROR(INDEX(③1일작업량DB!$H$6:$H$112,MATCH($C9&"|"&$D9,③1일작업량DB!$J$6:$J$112,0)),"-"),"") -> ㎥/일 | J9: =IF($F9="부록4",IFERROR(INDEX(③1일작업량DB!$G$6:$G$112,MATCH($C9&"|"&$D9,③1일작업량DB!$J$6:$J$112,0)),""),$I9) -> 42 | K9: 3 | L9: =IFERROR(IF(AND($G9>0,$J9>0,$K9>0),ROUNDUP($G9/($J9*$K9),1),0),0) -> 35.6 | M9: 0 | N9: 0 | O9: =$L9+$M9+$N9 -> 35.6
B10: =B9+1 -> 5 | C10: 토공 | D10: 표토제거 | E10: 표토제거/답외구간 | F10: 부록4 | G10: 1894 | H10: =IF($F10="부록4",IFERROR(INDEX(③1일작업량DB!$H$6:$H$112,MATCH($C10&"|"&$D10,③1일작업량DB!$J$6:$J$112,0)),"-"),"") -> ㎡/일 | J10: =IF($F10="부록4",IFERROR(INDEX(③1일작업량DB!$G$6:$G$112,MATCH($C10&"|"&$D10,③1일작업량DB!$J$6:$J$112,0)),""),$I10) -> 1915 | K10: 1 | L10: =IFERROR(IF(AND($G10>0,$J10>0,$K10>0),ROUNDUP($G10/($J10*$K10),1),0),0) -> 1 | M10: 0 | N10: 0 | O10: =$L10+$M10+$N10 -> 1
B11: =B10+1 -> 6 | C11: 기초 | D11: H-Pile 천공 | E11: 빗물펌프장 | F11: 부록4 | G11: 50 | H11: =IF($F11="부록4",IFERROR(INDEX(③1일작업량DB!$H$6:$H$112,MATCH($C11&"|"&$D11,③1일작업량DB!$J$6:$J$112,0)),"-"),"") -> 본/일 | J11: =IF($F11="부록4",IFERROR(INDEX(③1일작업량DB!$G$6:$G$112,MATCH($C11&"|"&$D11,③1일작업량DB!$J$6:$J$112,0)),""),$I11) -> 27 | K11: 3 | L11: =IFERROR(IF(AND($G11>0,$J11>0,$K11>0),ROUNDUP($G11/($J11*$K11),1),0),0) -> 0.7 | M11: 0 | N11: 0 | O11: =$L11+$M11+$N11 -> 0.7
B12: =B11+1 -> 7 | C12: 기초 | D12: 수평지보공(H-Beam)설치 | F12: 부록4 | G12: =56+192+104+38+118+56+18+56 -> 638 | H12: =IF($F12="부록4",IFERROR(INDEX(③1일작업량DB!$H$6:$H$112,MATCH($C12&"|"&$D12,③1일작업량DB!$J$6:$J$112,0)),"-"),"") -> 본/일 | J12: =IF($F12="부록4",IFERROR(INDEX(③1일작업량DB!$G$6:$G$112,MATCH($C12&"|"&$D12,③1일작업량DB!$J$6:$J$112,0)),""),$I12) -> 10 | K12: 3 | L12: =IFERROR(IF(AND($G12>0,$J12>0,$K12>0),ROUNDUP($G12/($J12*$K12),1),0),0) -> 21.3 | M12: 0 | N12: 0 | O12: =$L12+$M12+$N12 -> 21.3
B13: =B12+1 -> 8 | C13: 공통가설 | D13: 가설흙막이(강널말뚝) | E13: 유입관로 | F13: 부록4 | G13: 52 | H13: =IF($F13="부록4",IFERROR(INDEX(③1일작업량DB!$H$6:$H$112,MATCH($C13&"|"&$D13,③1일작업량DB!$J$6:$J$112,0)),"-"),"") -> 본/일 | J13: =IF($F13="부록4",IFERROR(INDEX(③1일작업량DB!$G$6:$G$112,MATCH($C13&"|"&$D13,③1일작업량DB!$J$6:$J$112,0)),""),$I13) -> 10 | K13: 3 | L13: =IFERROR(IF(AND($G13>0,$J13>0,$K13>0),ROUNDUP($G13/($J13*$K13),1),0),0) -> 1.8 | M13: 0 | N13: 0 | O13: =$L13+$M13+$N13 -> 1.8
B14: =B13+1 -> 9 | C14: 기초 | D14: 수평지보공(H-Beam)설치 | F14: 부록4 | G14: =8+5+1 -> 14 | H14: =IF($F14="부록4",IFERROR(INDEX(③1일작업량DB!$H$6:$H$112,MATCH($C14&"|"&$D14,③1일작업량DB!$J$6:$J$112,0)),"-"),"") -> 본/일 | J14: =IF($F14="부록4",IFERROR(INDEX(③1일작업량DB!$G$6:$G$112,MATCH($C14&"|"&$D14,③1일작업량DB!$J$6:$J$112,0)),""),$I14) -> 10 | K14: 3 | L14: =IFERROR(IF(AND($G14>0,$J14>0,$K14>0),ROUNDUP($G14/($J14*$K14),1),0),0) -> 0.5 | M14: 0 | N14: 0 | O14: =$L14+$M14+$N14 -> 0.5
B15: =B14+1 -> 10 | C15: 공통가설 | D15: 가설흙막이(강널말뚝) | E15: 추진구 | F15: 부록4 | G15: 92 | H15: =IF($F15="부록4",IFERROR(INDEX(③1일작업량DB!$H$6:$H$112,MATCH($C15&"|"&$D15,③1일작업량DB!$J$6:$J$112,0)),"-"),"") -> 본/일 | J15: =IF($F15="부록4",IFERROR(INDEX(③1일작업량DB!$G$6:$G$112,MATCH($C15&"|"&$D15,③1일작업량DB!$J$6:$J$112,0)),""),$I15) -> 10 | K15: 3 | L15: =IFERROR(IF(AND($G15>0,$J15>0,$K15>0),ROUNDUP($G15/($J15*$K15),1),0),0) -> 3.1 | M15: 0 | N15: 0 | O15: =$L15+$M15+$N15 -> 3.1
B16: =B15+1 -> 11 | C16: 기초 | D16: 수평지보공(H-Beam)설치 | F16: 부록4 | G16: =4+16 -> 20 | H16: =IF($F16="부록4",IFERROR(INDEX(③1일작업량DB!$H$6:$H$112,MATCH($C16&"|"&$D16,③1일작업량DB!$J$6:$J$112,0)),"-"),"") -> 본/일 | J16: =IF($F16="부록4",IFERROR(INDEX(③1일작업량DB!$G$6:$G$112,MATCH($C16&"|"&$D16,③1일작업량DB!$J$6:$J$112,0)),""),$I16) -> 10 | K16: 3 | L16: =IFERROR(IF(AND($G16>0,$J16>0,$K16>0),ROUNDUP($G16/($J16*$K16),1),0),0) -> 0.7 | M16: 0 | N16: 0 | O16: =$L16+$M16+$N16 -> 0.7
B17: =B16+1 -> 12 | C17: 철근콘크리트 | D17: 콘크리트타설(철근,f1-Ⅱ) | E17: 빗물펌프장 | F17: 부록4 | G17: 4513 | H17: =IF($F17="부록4",IFERROR(INDEX(③1일작업량DB!$H$6:$H$112,MATCH($C17&"|"&$D17,③1일작업량DB!$J$6:$J$112,0)),"-"),"") -> ㎥/일 | J17: =IF($F17="부록4",IFERROR(INDEX(③1일작업량DB!$G$6:$G$112,MATCH($C17&"|"&$D17,③1일작업량DB!$J$6:$J$112,0)),""),$I17) -> 130 | K17: 3 | L17: =IFERROR(IF(AND($G17>0,$J17>0,$K17>0),ROUNDUP($G17/($J17*$K17),1),0),0) -> 11.6 | M17: 3 | N17: 2 | O17: =$L17+$M17+$N17 -> 16.6
